<?xml version="1.0" encoding="UTF-8"?><testsuite name="nosetests" tests="232" errors="160" failures="4" skip="0"><testcase classname="pyvter.tests.test_df__delitem__.Test_del_item" name="test0" time="0.000"><error type="exceptions.IOError" message="[Errno 2] No such file or directory: 'data/error~subjectXtimeofdayXcourseXmodel_MISSING.csv'&#10;-------------------- &gt;&gt; begin captured logging &lt;&lt; --------------------&#10;matplotlib: DEBUG: $HOME=/home/jhd&#10;matplotlib: DEBUG: matplotlib data path /home/jhd/.local/share/virtualenvs/pyvter-QwCYsgP0/local/lib/python2.7/site-packages/matplotlib/mpl-data&#10;matplotlib: DEBUG: loaded rc file /home/jhd/.local/share/virtualenvs/pyvter-QwCYsgP0/local/lib/python2.7/site-packages/matplotlib/mpl-data/matplotlibrc&#10;matplotlib: DEBUG: matplotlib version 2.2.3&#10;matplotlib: DEBUG: interactive is False&#10;matplotlib: DEBUG: platform is linux2&#10;matplotlib: DEBUG: loaded modules: ['email.MIMEAudio', 'numpy.core.info', 'nose.plugins.doctest', 'nose.plugins.tempfile', 'ctypes.os', 'hotshot.warnings', 'hotshot.stats', 'gc', 'distutils.sysconfig', 'pkg_resources._vendor.traceback', 'nose.plugins.attrib', 'numpy.random.threading', 'logging.weakref', 'pyvter.collections', 'pprint', 'nose.plugins.logcapture', '_virtualenv_distutils.sys', 'nose.new', 'unittest.sys', 'numpy.core.umath', 'nose.os', 'string', 'numpy.lib.arraysetops', 'nose.plugins.__builtin__', 'encodings.utf_8', 'email.quoprimime', 'numpy.ctypeslib', 'json.encoder', 'subprocess', 'pyvter.math', '_ast', 'nose.plugins.optparse', 'email.codecs', 'numpy.ma.extras', 'numpy.fft.fftpack_lite', 'matplotlib.cbook', 'multiprocessing', 'dis', 'numpy.lib', 'logging.threading', 'pkg_resources._vendor.pprint', 'nose.plugins.multiprocessing', '_json', 'hotshot.profile', 'matplotlib.cbook.warnings', 'numpy.testing._private.pytesttester', 'pyparsing', 'matplotlib.cbook.textwrap', 'pkg_resources.extern.appdirs', 'hotshot.hotshot', 'pkg_resources._vendor.collections', 'numpy._globals', 'numpy.lib.npyio', 'xml.sax.io', 'email.random', 'pyvter.copy', 'nose.tools.unittest', 'nose.plugins.re', 'numpy.fft.helper', 'hotshot.log', 'nose.plugins.sys', 'matplotlib.rcsetup', 'optparse', 'unittest.suite', 'matplotlib', 'exceptions', 'json.scanner', 'codecs', 'numpy.os', 'email.socket', 'StringIO', '_hotshot', 'pkg_resources', 'weakref', 'numpy.core._internal', 'doctest', 'distutils.sys', 'numpy.lib.arraypad', 'base64', '_sre', 'email.FeedParser', 'email.charset', 'pkg_resources._vendor.datetime', 'pyvter.sys', 'select', 'ctypes._ctypes', '_heapq', 'six.moves.urllib', 'numpy.lib.financial', 'binascii', 'nose.plugins.os', 'email.MIMEMessage', 'email._parseaddr', 'email.sys', 'hotshot.parser', 'unittest.fnmatch', 'pkg_resources._vendor.six.moves.urllib', 'numpy.polynomial.chebyshev', 'pkg_resources.extern.six.moves.urllib', 'cPickle', 'numpy.polynomial.hermite_e', 'numpy.core.fromnumeric', 'nose.plugins', 'matplotlib._version', 'nose.plugins.xml', 'pkg_resources.os', 'pkg_resources._vendor.copy', 'encodings.aliases', 'fnmatch', 'sre_parse', 'pickle', 'numpy.random.warnings', 'xml.sax.types', 'distutils.email', 'logging.cStringIO', 'nose.time', 'numpy.lib.polynomial', 'numpy.compat', 'pkg_resources._vendor.os', 'pkg_resources.extern.six', 'numbers', 'nose.pyversion', 'numpy.core.records', 'email.message', 'email.Header', 'email.MIMEBase', 'strop', 'numpy.core.numeric', 'six', 'matplotlib.testing', 'csv', 'profile', 'nose.tools', 'numpy.linalg.lapack_lite', 'numpy.core._multiarray_tests', 'multiprocessing.sys', 'numpy.lib.arrayterator', 'email.parser', 'pkg_resources._vendor.__builtin__', 'os.path', 'nose.sys', 'pkg_resources.extern.packaging.specifiers', 'email.base64mime', '_weakrefset', 'nose.plugins.plugintest', 'unittest.traceback', 'unittest.os', 'numpy.version', 'functools', 'pkg_resources._vendor.weakref', 'sysconfig', 'email.MIMEImage', 'distutils.fancy_getopt', 'email.MIMEText', 'numpy.polynomial.legendre', 'nose.plugins.testid', 'nose.itertools', 'distutils.dep_util', '_bisect', 'numpy.matrixlib.defmatrix', 'tempfile', 'numpy.core.machar', 'imp', 'pkg_resources._vendor', 'multiprocessing.os', 'multiprocessing.itertools', 'nose.plugins.cover', 'pyvter.pprint', 'unittest.time', 'numpy.linalg.info', 'unittest.functools', 'pkg_resources._vendor.six', 'unittest.util', 'pkg_resources.errno', 'email.urllib', 'httplib', 'unittest.StringIO', 'decimal', 'numpy.lib._datasource', 'token', 'email.encoders', 'numpy.linalg._umath_linalg', 'cStringIO', 'cmd', 'nose.plugins.signal', 'numpy.add_newdocs', 'pyvter.__future__', 'multiprocessing.process', 'pkg_resources.extern.packaging.requirements', 'nose.loader', 'distutils.warnings', 'nose.traceback', 'nose.plugins.doctests', 'numpy.core.arrayprint', 'json.struct', 'numpy.lib.numpy', 'pkg_resources._vendor.packaging.__about__', 're', 'nose.plugins.traceback', 'email.quopri', 'sqlite3.time', 'math', 'ast', 'numpy.lib.ufunclike', 'nose.tools.nontrivial', 'ctypes.struct', 'numpy.testing._private', 'matplotlib.json', '_locale', 'logging', 'thread', 'sqlite3.dbapi2', 'traceback', 'nose.plugins.failuredetail', 'numpy.core', 'errno', 'multiprocessing.util', 'pkg_resources._vendor.packaging.markers', 'pkg_resources._vendor.packaging.version', '_collections', 'xml.sax.sys', 'nose.optparse', 'numpy.lib.twodim_base', 'distutils.util', 'array', 'email.Errors', 'nose.plugins.deprecated', 'ctypes.sys', 'posixpath', 'pkg_resources._vendor.packaging._compat', '_csv', 'nose.nose', 'types', 'numpy.lib.stride_tricks', 'numpy.lib.scimath', 'matplotlib.cbook.functools', 'pyvter.csv', 'json._json', 'xml.sax.os', 'pyvter.sqlite3', '_codecs', 'nose.core', 'email.feedparser', 'distutils.imp', 'email.time', 'hashlib', 'keyword', 'pkg_resources._vendor.pyparsing', 'numpy.lib.nanfunctions', 'xml.sax.saxutils', 'unittest.weakref', 'posix', 'nose.selector', 'sre_compile', 'pkg_resources._vendor.threading', '_hashlib', 'numpy.lib.shape_base', 'numpy._import_tools', 'logging.collections', 'email.base64', 'nose.plugins.threading', 'nose.plugins.unittest', 'multiprocessing.atexit', 'numpy.sys', 'dateutil._version', 'unittest.result', 'bz2', 'nose.config', 'encodings.codecs', 'email.MIMEMultipart', 'email.string', 'unittest.difflib', '_ssl', 'numpy.lib.index_tricks', 'warnings', 'glob', 'abc', '_sqlite3', 'numpy.__config__', 'nose.plugins.StringIO', 'multiprocessing._multiprocessing', 'bdb', '_virtualenv_distutils', 'pkg_resources.extern.six.moves', 'nose.tools.trivial', 'nose.plugins.pickle', 'numpy.linalg.linalg', 'nose.plugins.debug', 'nose.ConfigParser', 'numpy.lib._iotools', 'email.iterators', 'random', 'unittest.types', 'nose.plugins.isolate', 'datetime', 'distutils.getopt', 'logging.os', 'ctypes._endian', 'encodings.encodings', 'unittest.pprint', 'matplotlib.sys', 'nose.cStringIO', 'numpy.random.mtrand', 'xml', 'copy', 'importlib', 'nose.stat', 'six.moves.urllib.request', 'numpy.linalg', 'pkg_resources._vendor.warnings', 'logging.thread', 'numpy.lib._version', 'nose.plugins.__future__', 'zipfile', 'repr', 'ssl', 'hotshot', 'new', 'distutils.re', 'nose.plugins.errorclass', 'nose.plugins.inspect', 'nose.plugins.pkg_resources', 'numpy.lib.type_check', 'resource', 'bisect', 'unittest.runner', 'nose.__future__', 'unittest.re', 'threading', 'nose.plugins.skip', 'pkg_resources._vendor.six.moves', 'nose.failure', 'hotshot._hotshot', 'cycler', 'email.Message', 'pyvter.base', 'locale', 'atexit', 'email.quopriMIME', 'pkg_resources._vendor.re', 'calendar', 'matplotlib._color_data', 'nose.imp', 'dateutil', 'plistlib', 'numpy.lib.histograms', 'urllib', 'sqlite3.collections', 'nose.plugins.xunit', 'pkg_resources.extern.packaging.version', 'nose.tokenize', 'pkg_resources._vendor.string', 'pkg_resources.sys', 'email', 'fcntl', 'unittest.case', 'distutils.os', 'Queue', 'numpy.lib.info', 'ctypes', '_ctypes', 'nose.inspector', 'json.re', 'nose.plugins.hotshot', 'nose.importer', 'unittest.signal', 'itertools', 'distutils.spawn', 'opcode', 'pstats', 'pdb', 'six.moves', 'numpy.testing._private.nosetester', 'email.uu', 'nose.plugins.codecs', 'unittest', 'sqlite3.datetime', 'email.calendar', 'nose.util', 'numpy.testing._private.utils', 'distutils.debug', 'unittest.collections', 'pkgutil', 'platform', 'nose.plugins.base', 'sre_constants', 'numpy.core._methods', 'numpy.core.function_base', 'numpy.compat.py3k', 'pkg_resources._vendor.sre_constants', 'numpy', 'parser', 'subprocess32', 'email.utils', 'numpy.ma', 'nose.plugins.builtin', 'logging.atexit', 'matplotlib.cbook._backports', 'hotshot.symbol', 'email.MIMENonMultipart', 'email.email', 'zlib', 'nose.plugins.capture', 'nose.types', 'multiprocessing.weakref', 'json.decoder', 'distutils.distutils', 'copy_reg', 'pkg_resources._vendor.packaging.specifiers', 'pkg_resources._vendor.appdirs', 'nose.plugins.logging', '__main__', 'site', 'nose.proxy', 'io', 'numpy.fft.info', 'distutils.opcode', 'shutil', 'nose.plugins.time', 'numpy.fft.fftpack', 'email.binascii', 'nose.tools.re', 'sqlite3', 'pkg_resources.extern', 'numpy.lib.utils', 'numpy.random', 'rfc822', 'numpy.polynomial.polyutils', 'json.json', 'email.re', 'sys', 'numpy.compat._inspect', 'multiprocessing.subprocess', 'nose.logging', 'email.cStringIO', 'pkg_resources._vendor.packaging', 'matplotlib.fontconfig_pattern', '_weakref', 'difflib', 'distutils.errors', 'pkg_resources.extern.pyparsing', 'urlparse', 'unittest.warnings', 'gzip', 'nose.case', 'heapq', 'xml.sax.urlparse', 'distutils', 'numpy.core.einsumfunc', 'pkg_resources.extern.packaging', 'matplotlib.cbook.deprecation', 'matplotlib.colors', 'email.mime', 'struct', 'numpy.random.info', 'xml.sax.urllib', 'sqlite3._sqlite3', 'numpy.testing', '_abcoll', 'collections', 'pkg_resources._vendor.sys', 'unittest.main', 'email.Parser', 'distutils.types', 'nose.plugins.pdb', 'zipimport', 'pkg_resources._vendor.packaging._structures', 'pkg_resources.extern.sys', 'pkg_resources.extern.packaging.markers', 'nose.plugins.cStringIO', 'textwrap', 'ConfigParser', 'multiprocessing.multiprocessing', 'signal', 'numpy.random.operator', 'nose', 'numpy.core.multiarray', 'quopri', 'distutils.log', 'distutils.version', 'pkg_resources.py31compat', 'numpy.ma.core', 'numpy.core.getlimits', 'hotshot.os', 'nose.plugins.collect', 'nose.unittest', 'logging.traceback', 'numpy.matrixlib', '_multiprocessing', 'backports', 'nose.warnings', 'numpy.lib.mixins', '_posixsubprocess32', 'email.errors', 'nose.plugins.manager', 'encodings.ascii', 'mpl_toolkits', 'UserDict', 'inspect', 'numpy.polynomial.laguerre', 'logging.sys', 'unittest.loader', 'pyvter.itertools', '_functools', 'json.sys', 'email.Iterators', 'socket', 'numpy.core.memmap', 'email.base64MIME', 'cython_runtime', 'nose.result', 'email.Charset', 'nose.suite', 'nose.plugins.prof', 'os', 'marshal', '__future__', 'numpy.core.shape_base', 'matplotlib.compat', '__builtin__', 'nose.re', 'numpy.polynomial', 'xml.sax.xmlreader', 'pyvter.inspect', 'operator', 'distutils.string', 'multiprocessing.threading', 'pkg_resources._vendor.packaging.requirements', '_socket', 'json', 'email.Utils', 'xml.sax.handler', 'distutils.stat', 'numpy.core.numerictypes', '_warnings', 'encodings.__builtin__', 'nose.plugins.cPickle', 'tokenize', 'email.os', 'numpy._distributor_init', 'nose.plugins.itertools', 'pwd', 'nose.plugins.nose', 'distutils.dist', 'nose.plugins.Queue', '_struct', 'pyvter', 'nose.textwrap', 'uu', 'numpy.fft', 'numpy.random.numpy', 'logging.time', 'matplotlib.compat.subprocess', 'numpy.lib.function_base', 'logging.warnings', 'nose.plugins.textwrap', 'mimetools', 'nose.exc', 'multiprocessing.signal', 'xml.sax', 'nose.inspect', 'logging.codecs', '_random', 'encodings', 'numpy.polynomial._polybase', 'numpy.polynomial.hermite', 'contextlib', 'distutils.fnmatch', 'numpy.polynomial.polynomial', 'email.Generator', '_io', 'importlib.sys', 'grp', 'linecache', 'numpy.core.defchararray', 'gettext', 'nose.tools.nose', 'email.warnings', 'getopt', 'xml.sax._exceptions', 'genericpath', 'stat', 'symbol', 'urllib2', 'unittest.signals', 'email.Encoders', 'backports.functools_lru_cache', 'ctypes.ctypes', 'nose.plugins.multiprocess', 'numpy.lib.format', 'hotshot.pstats', 'sitecustomize', 'numpy.testing._private.decorators', 'nose.plugins.allmodules', 'pkg_resources._vendor.types', 'nose.tools.time', 'time', 'pyvter.warnings', 'nose.plugins.warnings', 'future_builtins']&#10;matplotlib: DEBUG: CACHEDIR=/home/jhd/.cache/matplotlib&#10;matplotlib.font_manager: DEBUG: Using fontManager instance from /home/jhd/.cache/matplotlib/fontList.json&#10;matplotlib.backends: DEBUG: backend TkAgg version unknown&#10;--------------------- &gt;&gt; end captured logging &lt;&lt; ---------------------"><![CDATA[  File "/usr/lib/python2.7/unittest/case.py", line 320, in run
    self.setUp()
  File "/home/jhd/Documents/Projects/pyvter/tests/test_df__delitem__.py", line 27, in setUp
    self.df.read_tbl('data/error~subjectXtimeofdayXcourseXmodel_MISSING.csv')
  File "/home/jhd/Documents/Projects/pyvter/base.py", line 199, in read_tbl
    fid = open(fname, 'r')
"[Errno 2] No such file or directory: 'data/error~subjectXtimeofdayXcourseXmodel_MISSING.csv'\n-------------------- >> begin captured logging << --------------------\nmatplotlib: DEBUG: $HOME=/home/jhd\nmatplotlib: DEBUG: matplotlib data path /home/jhd/.local/share/virtualenvs/pyvter-QwCYsgP0/local/lib/python2.7/site-packages/matplotlib/mpl-data\nmatplotlib: DEBUG: loaded rc file /home/jhd/.local/share/virtualenvs/pyvter-QwCYsgP0/local/lib/python2.7/site-packages/matplotlib/mpl-data/matplotlibrc\nmatplotlib: DEBUG: matplotlib version 2.2.3\nmatplotlib: DEBUG: interactive is False\nmatplotlib: DEBUG: platform is linux2\nmatplotlib: DEBUG: loaded modules: ['email.MIMEAudio', 'numpy.core.info', 'nose.plugins.doctest', 'nose.plugins.tempfile', 'ctypes.os', 'hotshot.warnings', 'hotshot.stats', 'gc', 'distutils.sysconfig', 'pkg_resources._vendor.traceback', 'nose.plugins.attrib', 'numpy.random.threading', 'logging.weakref', 'pyvter.collections', 'pprint', 'nose.plugins.logcapture', '_virtualenv_distutils.sys', 'nose.new', 'unittest.sys', 'numpy.core.umath', 'nose.os', 'string', 'numpy.lib.arraysetops', 'nose.plugins.__builtin__', 'encodings.utf_8', 'email.quoprimime', 'numpy.ctypeslib', 'json.encoder', 'subprocess', 'pyvter.math', '_ast', 'nose.plugins.optparse', 'email.codecs', 'numpy.ma.extras', 'numpy.fft.fftpack_lite', 'matplotlib.cbook', 'multiprocessing', 'dis', 'numpy.lib', 'logging.threading', 'pkg_resources._vendor.pprint', 'nose.plugins.multiprocessing', '_json', 'hotshot.profile', 'matplotlib.cbook.warnings', 'numpy.testing._private.pytesttester', 'pyparsing', 'matplotlib.cbook.textwrap', 'pkg_resources.extern.appdirs', 'hotshot.hotshot', 'pkg_resources._vendor.collections', 'numpy._globals', 'numpy.lib.npyio', 'xml.sax.io', 'email.random', 'pyvter.copy', 'nose.tools.unittest', 'nose.plugins.re', 'numpy.fft.helper', 'hotshot.log', 'nose.plugins.sys', 'matplotlib.rcsetup', 'optparse', 'unittest.suite', 'matplotlib', 'exceptions', 'json.scanner', 'codecs', 'numpy.os', 'email.socket', 'StringIO', '_hotshot', 'pkg_resources', 'weakref', 'numpy.core._internal', 'doctest', 'distutils.sys', 'numpy.lib.arraypad', 'base64', '_sre', 'email.FeedParser', 'email.charset', 'pkg_resources._vendor.datetime', 'pyvter.sys', 'select', 'ctypes._ctypes', '_heapq', 'six.moves.urllib', 'numpy.lib.financial', 'binascii', 'nose.plugins.os', 'email.MIMEMessage', 'email._parseaddr', 'email.sys', 'hotshot.parser', 'unittest.fnmatch', 'pkg_resources._vendor.six.moves.urllib', 'numpy.polynomial.chebyshev', 'pkg_resources.extern.six.moves.urllib', 'cPickle', 'numpy.polynomial.hermite_e', 'numpy.core.fromnumeric', 'nose.plugins', 'matplotlib._version', 'nose.plugins.xml', 'pkg_resources.os', 'pkg_resources._vendor.copy', 'encodings.aliases', 'fnmatch', 'sre_parse', 'pickle', 'numpy.random.warnings', 'xml.sax.types', 'distutils.email', 'logging.cStringIO', 'nose.time', 'numpy.lib.polynomial', 'numpy.compat', 'pkg_resources._vendor.os', 'pkg_resources.extern.six', 'numbers', 'nose.pyversion', 'numpy.core.records', 'email.message', 'email.Header', 'email.MIMEBase', 'strop', 'numpy.core.numeric', 'six', 'matplotlib.testing', 'csv', 'profile', 'nose.tools', 'numpy.linalg.lapack_lite', 'numpy.core._multiarray_tests', 'multiprocessing.sys', 'numpy.lib.arrayterator', 'email.parser', 'pkg_resources._vendor.__builtin__', 'os.path', 'nose.sys', 'pkg_resources.extern.packaging.specifiers', 'email.base64mime', '_weakrefset', 'nose.plugins.plugintest', 'unittest.traceback', 'unittest.os', 'numpy.version', 'functools', 'pkg_resources._vendor.weakref', 'sysconfig', 'email.MIMEImage', 'distutils.fancy_getopt', 'email.MIMEText', 'numpy.polynomial.legendre', 'nose.plugins.testid', 'nose.itertools', 'distutils.dep_util', '_bisect', 'numpy.matrixlib.defmatrix', 'tempfile', 'numpy.core.machar', 'imp', 'pkg_resources._vendor', 'multiprocessing.os', 'multiprocessing.itertools', 'nose.plugins.cover', 'pyvter.pprint', 'unittest.time', 'numpy.linalg.info', 'unittest.functools', 'pkg_resources._vendor.six', 'unittest.util', 'pkg_resources.errno', 'email.urllib', 'httplib', 'unittest.StringIO', 'decimal', 'numpy.lib._datasource', 'token', 'email.encoders', 'numpy.linalg._umath_linalg', 'cStringIO', 'cmd', 'nose.plugins.signal', 'numpy.add_newdocs', 'pyvter.__future__', 'multiprocessing.process', 'pkg_resources.extern.packaging.requirements', 'nose.loader', 'distutils.warnings', 'nose.traceback', 'nose.plugins.doctests', 'numpy.core.arrayprint', 'json.struct', 'numpy.lib.numpy', 'pkg_resources._vendor.packaging.__about__', 're', 'nose.plugins.traceback', 'email.quopri', 'sqlite3.time', 'math', 'ast', 'numpy.lib.ufunclike', 'nose.tools.nontrivial', 'ctypes.struct', 'numpy.testing._private', 'matplotlib.json', '_locale', 'logging', 'thread', 'sqlite3.dbapi2', 'traceback', 'nose.plugins.failuredetail', 'numpy.core', 'errno', 'multiprocessing.util', 'pkg_resources._vendor.packaging.markers', 'pkg_resources._vendor.packaging.version', '_collections', 'xml.sax.sys', 'nose.optparse', 'numpy.lib.twodim_base', 'distutils.util', 'array', 'email.Errors', 'nose.plugins.deprecated', 'ctypes.sys', 'posixpath', 'pkg_resources._vendor.packaging._compat', '_csv', 'nose.nose', 'types', 'numpy.lib.stride_tricks', 'numpy.lib.scimath', 'matplotlib.cbook.functools', 'pyvter.csv', 'json._json', 'xml.sax.os', 'pyvter.sqlite3', '_codecs', 'nose.core', 'email.feedparser', 'distutils.imp', 'email.time', 'hashlib', 'keyword', 'pkg_resources._vendor.pyparsing', 'numpy.lib.nanfunctions', 'xml.sax.saxutils', 'unittest.weakref', 'posix', 'nose.selector', 'sre_compile', 'pkg_resources._vendor.threading', '_hashlib', 'numpy.lib.shape_base', 'numpy._import_tools', 'logging.collections', 'email.base64', 'nose.plugins.threading', 'nose.plugins.unittest', 'multiprocessing.atexit', 'numpy.sys', 'dateutil._version', 'unittest.result', 'bz2', 'nose.config', 'encodings.codecs', 'email.MIMEMultipart', 'email.string', 'unittest.difflib', '_ssl', 'numpy.lib.index_tricks', 'warnings', 'glob', 'abc', '_sqlite3', 'numpy.__config__', 'nose.plugins.StringIO', 'multiprocessing._multiprocessing', 'bdb', '_virtualenv_distutils', 'pkg_resources.extern.six.moves', 'nose.tools.trivial', 'nose.plugins.pickle', 'numpy.linalg.linalg', 'nose.plugins.debug', 'nose.ConfigParser', 'numpy.lib._iotools', 'email.iterators', 'random', 'unittest.types', 'nose.plugins.isolate', 'datetime', 'distutils.getopt', 'logging.os', 'ctypes._endian', 'encodings.encodings', 'unittest.pprint', 'matplotlib.sys', 'nose.cStringIO', 'numpy.random.mtrand', 'xml', 'copy', 'importlib', 'nose.stat', 'six.moves.urllib.request', 'numpy.linalg', 'pkg_resources._vendor.warnings', 'logging.thread', 'numpy.lib._version', 'nose.plugins.__future__', 'zipfile', 'repr', 'ssl', 'hotshot', 'new', 'distutils.re', 'nose.plugins.errorclass', 'nose.plugins.inspect', 'nose.plugins.pkg_resources', 'numpy.lib.type_check', 'resource', 'bisect', 'unittest.runner', 'nose.__future__', 'unittest.re', 'threading', 'nose.plugins.skip', 'pkg_resources._vendor.six.moves', 'nose.failure', 'hotshot._hotshot', 'cycler', 'email.Message', 'pyvter.base', 'locale', 'atexit', 'email.quopriMIME', 'pkg_resources._vendor.re', 'calendar', 'matplotlib._color_data', 'nose.imp', 'dateutil', 'plistlib', 'numpy.lib.histograms', 'urllib', 'sqlite3.collections', 'nose.plugins.xunit', 'pkg_resources.extern.packaging.version', 'nose.tokenize', 'pkg_resources._vendor.string', 'pkg_resources.sys', 'email', 'fcntl', 'unittest.case', 'distutils.os', 'Queue', 'numpy.lib.info', 'ctypes', '_ctypes', 'nose.inspector', 'json.re', 'nose.plugins.hotshot', 'nose.importer', 'unittest.signal', 'itertools', 'distutils.spawn', 'opcode', 'pstats', 'pdb', 'six.moves', 'numpy.testing._private.nosetester', 'email.uu', 'nose.plugins.codecs', 'unittest', 'sqlite3.datetime', 'email.calendar', 'nose.util', 'numpy.testing._private.utils', 'distutils.debug', 'unittest.collections', 'pkgutil', 'platform', 'nose.plugins.base', 'sre_constants', 'numpy.core._methods', 'numpy.core.function_base', 'numpy.compat.py3k', 'pkg_resources._vendor.sre_constants', 'numpy', 'parser', 'subprocess32', 'email.utils', 'numpy.ma', 'nose.plugins.builtin', 'logging.atexit', 'matplotlib.cbook._backports', 'hotshot.symbol', 'email.MIMENonMultipart', 'email.email', 'zlib', 'nose.plugins.capture', 'nose.types', 'multiprocessing.weakref', 'json.decoder', 'distutils.distutils', 'copy_reg', 'pkg_resources._vendor.packaging.specifiers', 'pkg_resources._vendor.appdirs', 'nose.plugins.logging', '__main__', 'site', 'nose.proxy', 'io', 'numpy.fft.info', 'distutils.opcode', 'shutil', 'nose.plugins.time', 'numpy.fft.fftpack', 'email.binascii', 'nose.tools.re', 'sqlite3', 'pkg_resources.extern', 'numpy.lib.utils', 'numpy.random', 'rfc822', 'numpy.polynomial.polyutils', 'json.json', 'email.re', 'sys', 'numpy.compat._inspect', 'multiprocessing.subprocess', 'nose.logging', 'email.cStringIO', 'pkg_resources._vendor.packaging', 'matplotlib.fontconfig_pattern', '_weakref', 'difflib', 'distutils.errors', 'pkg_resources.extern.pyparsing', 'urlparse', 'unittest.warnings', 'gzip', 'nose.case', 'heapq', 'xml.sax.urlparse', 'distutils', 'numpy.core.einsumfunc', 'pkg_resources.extern.packaging', 'matplotlib.cbook.deprecation', 'matplotlib.colors', 'email.mime', 'struct', 'numpy.random.info', 'xml.sax.urllib', 'sqlite3._sqlite3', 'numpy.testing', '_abcoll', 'collections', 'pkg_resources._vendor.sys', 'unittest.main', 'email.Parser', 'distutils.types', 'nose.plugins.pdb', 'zipimport', 'pkg_resources._vendor.packaging._structures', 'pkg_resources.extern.sys', 'pkg_resources.extern.packaging.markers', 'nose.plugins.cStringIO', 'textwrap', 'ConfigParser', 'multiprocessing.multiprocessing', 'signal', 'numpy.random.operator', 'nose', 'numpy.core.multiarray', 'quopri', 'distutils.log', 'distutils.version', 'pkg_resources.py31compat', 'numpy.ma.core', 'numpy.core.getlimits', 'hotshot.os', 'nose.plugins.collect', 'nose.unittest', 'logging.traceback', 'numpy.matrixlib', '_multiprocessing', 'backports', 'nose.warnings', 'numpy.lib.mixins', '_posixsubprocess32', 'email.errors', 'nose.plugins.manager', 'encodings.ascii', 'mpl_toolkits', 'UserDict', 'inspect', 'numpy.polynomial.laguerre', 'logging.sys', 'unittest.loader', 'pyvter.itertools', '_functools', 'json.sys', 'email.Iterators', 'socket', 'numpy.core.memmap', 'email.base64MIME', 'cython_runtime', 'nose.result', 'email.Charset', 'nose.suite', 'nose.plugins.prof', 'os', 'marshal', '__future__', 'numpy.core.shape_base', 'matplotlib.compat', '__builtin__', 'nose.re', 'numpy.polynomial', 'xml.sax.xmlreader', 'pyvter.inspect', 'operator', 'distutils.string', 'multiprocessing.threading', 'pkg_resources._vendor.packaging.requirements', '_socket', 'json', 'email.Utils', 'xml.sax.handler', 'distutils.stat', 'numpy.core.numerictypes', '_warnings', 'encodings.__builtin__', 'nose.plugins.cPickle', 'tokenize', 'email.os', 'numpy._distributor_init', 'nose.plugins.itertools', 'pwd', 'nose.plugins.nose', 'distutils.dist', 'nose.plugins.Queue', '_struct', 'pyvter', 'nose.textwrap', 'uu', 'numpy.fft', 'numpy.random.numpy', 'logging.time', 'matplotlib.compat.subprocess', 'numpy.lib.function_base', 'logging.warnings', 'nose.plugins.textwrap', 'mimetools', 'nose.exc', 'multiprocessing.signal', 'xml.sax', 'nose.inspect', 'logging.codecs', '_random', 'encodings', 'numpy.polynomial._polybase', 'numpy.polynomial.hermite', 'contextlib', 'distutils.fnmatch', 'numpy.polynomial.polynomial', 'email.Generator', '_io', 'importlib.sys', 'grp', 'linecache', 'numpy.core.defchararray', 'gettext', 'nose.tools.nose', 'email.warnings', 'getopt', 'xml.sax._exceptions', 'genericpath', 'stat', 'symbol', 'urllib2', 'unittest.signals', 'email.Encoders', 'backports.functools_lru_cache', 'ctypes.ctypes', 'nose.plugins.multiprocess', 'numpy.lib.format', 'hotshot.pstats', 'sitecustomize', 'numpy.testing._private.decorators', 'nose.plugins.allmodules', 'pkg_resources._vendor.types', 'nose.tools.time', 'time', 'pyvter.warnings', 'nose.plugins.warnings', 'future_builtins']\nmatplotlib: DEBUG: CACHEDIR=/home/jhd/.cache/matplotlib\nmatplotlib.font_manager: DEBUG: Using fontManager instance from /home/jhd/.cache/matplotlib/fontList.json\nmatplotlib.backends: DEBUG: backend TkAgg version unknown\n--------------------- >> end captured logging << ---------------------"]]></error></testcase><testcase classname="pyvter.tests.test_df__delitem__.Test_del_item" name="test1" time="0.000"><error type="exceptions.IOError" message="[Errno 2] No such file or directory: 'data/error~subjectXtimeofdayXcourseXmodel_MISSING.csv'"><![CDATA[Traceback (most recent call last):
  File "/usr/lib/python2.7/unittest/case.py", line 320, in run
    self.setUp()
  File "/home/jhd/Documents/Projects/pyvter/tests/test_df__delitem__.py", line 27, in setUp
    self.df.read_tbl('data/error~subjectXtimeofdayXcourseXmodel_MISSING.csv')
  File "/home/jhd/Documents/Projects/pyvter/base.py", line 199, in read_tbl
    fid = open(fname, 'r')
IOError: [Errno 2] No such file or directory: 'data/error~subjectXtimeofdayXcourseXmodel_MISSING.csv'
]]></error></testcase><testcase classname="pyvter.tests.test_df__delitem__.Test_del_item" name="test3" time="0.000"><error type="exceptions.IOError" message="[Errno 2] No such file or directory: 'data/error~subjectXtimeofdayXcourseXmodel_MISSING.csv'"><![CDATA[Traceback (most recent call last):
  File "/usr/lib/python2.7/unittest/case.py", line 320, in run
    self.setUp()
  File "/home/jhd/Documents/Projects/pyvter/tests/test_df__delitem__.py", line 27, in setUp
    self.df.read_tbl('data/error~subjectXtimeofdayXcourseXmodel_MISSING.csv')
  File "/home/jhd/Documents/Projects/pyvter/base.py", line 199, in read_tbl
    fid = open(fname, 'r')
IOError: [Errno 2] No such file or directory: 'data/error~subjectXtimeofdayXcourseXmodel_MISSING.csv'
]]></error></testcase><testcase classname="pyvter.tests.test_df__determine_sqlite3_type.Test__checktype" name="test0" time="0.000"></testcase><testcase classname="pyvter.tests.test_df__determine_sqlite3_type.Test__checktype" name="test1" time="0.000"></testcase><testcase classname="pyvter.tests.test_df__determine_sqlite3_type.Test__checktype" name="test2" time="0.000"></testcase><testcase classname="pyvter.tests.test_df__determine_sqlite3_type.Test__checktype" name="test3" time="0.000"></testcase><testcase classname="pyvter.tests.test_df__determine_sqlite3_type.Test__checktype" name="test4" time="0.000"></testcase><testcase classname="pyvter.tests.test_df__determine_sqlite3_type.Test__checktype" name="test5" time="0.000"></testcase><testcase classname="pyvter.tests.test_df__determine_sqlite3_type.Test__checktype" name="test6" time="0.000"></testcase><testcase classname="pyvter.tests.test_df__setitem__.Test__setitem__" name="test1" time="0.000"><error type="exceptions.IOError" message="[Errno 2] No such file or directory: 'data/error~subjectXtimeofdayXcourseXmodel_MISSING.csv'"><![CDATA[Traceback (most recent call last):
  File "/usr/lib/python2.7/unittest/case.py", line 329, in run
    testMethod()
  File "/home/jhd/Documents/Projects/pyvter/tests/test_df__setitem__.py", line 36, in test1
    df.read_tbl('data/error~subjectXtimeofdayXcourseXmodel_MISSING.csv')
  File "/home/jhd/Documents/Projects/pyvter/base.py", line 199, in read_tbl
    fid = open(fname, 'r')
IOError: [Errno 2] No such file or directory: 'data/error~subjectXtimeofdayXcourseXmodel_MISSING.csv'
]]></error></testcase><testcase classname="pyvter.tests.test_df__setitem__.Test__setitem__" name="test11" time="0.000"></testcase><testcase classname="pyvter.tests.test_df__setitem__.Test__setitem__" name="test12" time="0.000"></testcase><testcase classname="pyvter.tests.test_df__setitem__.Test__setitem__" name="test2" time="0.000"></testcase><testcase classname="pyvter.tests.test_df__setitem__.Test__setitem__" name="test21" time="0.000"></testcase><testcase classname="pyvter.tests.test_df__setitem__.Test__setitem__" name="test3" time="0.000"></testcase><testcase classname="pyvter.tests.test_df__setitem__.Test__setitem__" name="test_kn" time="0.000"><error type="exceptions.IOError" message="[Errno 2] No such file or directory: 'data/example.csv'"><![CDATA[Traceback (most recent call last):
  File "/usr/lib/python2.7/unittest/case.py", line 329, in run
    testMethod()
  File "/home/jhd/Documents/Projects/pyvter/tests/test_df__setitem__.py", line 87, in test_kn
    df.read_tbl('data/example.csv')
  File "/home/jhd/Documents/Projects/pyvter/base.py", line 199, in read_tbl
    fid = open(fname, 'r')
IOError: [Errno 2] No such file or directory: 'data/example.csv'
]]></error></testcase><testcase classname="pyvter.tests.test_df__str__.Test_df__str__" name="test0" time="0.000"><error type="exceptions.IOError" message="[Errno 2] No such file or directory: 'data/error~subjectXtimeofdayXcourseXmodel_MISSING.csv'"><![CDATA[Traceback (most recent call last):
  File "/usr/lib/python2.7/unittest/case.py", line 329, in run
    testMethod()
  File "/home/jhd/Documents/Projects/pyvter/tests/test_df__str__.py", line 77, in test0
    df.read_tbl('data/error~subjectXtimeofdayXcourseXmodel_MISSING.csv')
  File "/home/jhd/Documents/Projects/pyvter/base.py", line 199, in read_tbl
    fid = open(fname, 'r')
IOError: [Errno 2] No such file or directory: 'data/error~subjectXtimeofdayXcourseXmodel_MISSING.csv'
]]></error></testcase><testcase classname="pyvter.tests.test_df_are_col_lengths_equal.Test__are_col_lengths_equal" name="test0" time="0.000"></testcase><testcase classname="pyvter.tests.test_df_are_col_lengths_equal.Test__are_col_lengths_equal" name="test1" time="0.000"></testcase><testcase classname="pyvter.tests.test_df_are_col_lengths_equal.Test__are_col_lengths_equal" name="test2" time="0.000"></testcase><testcase classname="pyvter.tests.test_df_are_col_lengths_equal.Test__are_col_lengths_equal" name="test3" time="0.000"></testcase><testcase classname="pyvter.tests.test_df_attach.Test_attach" name="test0" time="0.000"><error type="exceptions.IOError" message="[Errno 2] No such file or directory: 'data/words~ageXcondition.csv'"><![CDATA[Traceback (most recent call last):
  File "/usr/lib/python2.7/unittest/case.py", line 329, in run
    testMethod()
  File "/home/jhd/Documents/Projects/pyvter/tests/test_df_attach.py", line 27, in test0
    self.df1.read_tbl('data/words~ageXcondition.csv')
  File "/home/jhd/Documents/Projects/pyvter/base.py", line 199, in read_tbl
    fid = open(fname, 'r')
IOError: [Errno 2] No such file or directory: 'data/words~ageXcondition.csv'
]]></error></testcase><testcase classname="pyvter.tests.test_df_attach.Test_attach" name="test1" time="0.000"><error type="exceptions.IOError" message="[Errno 2] No such file or directory: 'data/words~ageXcondition.csv'"><![CDATA[Traceback (most recent call last):
  File "/usr/lib/python2.7/unittest/case.py", line 329, in run
    testMethod()
  File "/home/jhd/Documents/Projects/pyvter/tests/test_df_attach.py", line 38, in test1
    self.df1.read_tbl('data/words~ageXcondition.csv')
  File "/home/jhd/Documents/Projects/pyvter/base.py", line 199, in read_tbl
    fid = open(fname, 'r')
IOError: [Errno 2] No such file or directory: 'data/words~ageXcondition.csv'
]]></error></testcase><testcase classname="pyvter.tests.test_df_attach.Test_attach" name="test2" time="0.000"><error type="exceptions.IOError" message="[Errno 2] No such file or directory: 'data/words~ageXcondition.csv'"><![CDATA[Traceback (most recent call last):
  File "/usr/lib/python2.7/unittest/case.py", line 329, in run
    testMethod()
  File "/home/jhd/Documents/Projects/pyvter/tests/test_df_attach.py", line 53, in test2
    df1.read_tbl('data/words~ageXcondition.csv')
  File "/home/jhd/Documents/Projects/pyvter/base.py", line 199, in read_tbl
    fid = open(fname, 'r')
IOError: [Errno 2] No such file or directory: 'data/words~ageXcondition.csv'
]]></error></testcase><testcase classname="pyvter.tests.test_df_build_sqlite3_tbl.Test__build_sqlite3_tbl" name="test00" time="0.001"></testcase><testcase classname="pyvter.tests.test_df_build_sqlite3_tbl.Test__build_sqlite3_tbl" name="test01" time="0.001"></testcase><testcase classname="pyvter.tests.test_df_build_sqlite3_tbl.Test__build_sqlite3_tbl" name="test02" time="0.001"></testcase><testcase classname="pyvter.tests.test_df_build_sqlite3_tbl.Test__build_sqlite3_tbl" name="test1" time="0.001"></testcase><testcase classname="pyvter.tests.test_df_build_sqlite3_tbl.Test__build_sqlite3_tbl" name="test2" time="0.001"></testcase><testcase classname="pyvter.tests.test_df_build_sqlite3_tbl.Test__build_sqlite3_tbl" name="test21" time="0.001"></testcase><testcase classname="pyvter.tests.test_df_build_sqlite3_tbl.Test__build_sqlite3_tbl" name="test22" time="0.001"></testcase><testcase classname="pyvter.tests.test_df_build_sqlite3_tbl.Test__build_sqlite3_tbl" name="test3" time="0.001"></testcase><testcase classname="pyvter.tests.test_df_build_sqlite3_tbl.Test__build_sqlite3_tbl" name="test31" time="0.001"></testcase><testcase classname="pyvter.tests.test_df_build_sqlite3_tbl.Test__build_sqlite3_tbl" name="test4" time="0.001"></testcase><testcase classname="pyvter.tests.test_df_insert.Test_insert" name="test0" time="0.007"></testcase><testcase classname="pyvter.tests.test_df_insert.Test_insert" name="test1" time="0.000"></testcase><testcase classname="pyvter.tests.test_df_insert.Test_insert" name="test2" time="0.000"></testcase><testcase classname="pyvter.tests.test_df_insert.Test_insert" name="test3" time="0.000"></testcase><testcase classname="pyvter.tests.test_df_insert.Test_insert" name="test4" time="0.000"></testcase><testcase classname="pyvter.tests.test_df_insert.Test_insert" name="test5" time="0.002"><system-out><![CDATA[0.001702
]]></system-out></testcase><testcase classname="pyvter.tests.test_df_read_tbl.Test_read_tbl" name="test00" time="0.000"><error type="exceptions.IOError" message="[Errno 2] No such file or directory: 'data/skiptest.csv'"><![CDATA[Traceback (most recent call last):
  File "/usr/lib/python2.7/unittest/case.py", line 329, in run
    testMethod()
  File "/home/jhd/Documents/Projects/pyvter/tests/test_df_read_tbl.py", line 41, in test00
    self.df.read_tbl('data/skiptest.csv',skip=4)
  File "/home/jhd/Documents/Projects/pyvter/base.py", line 199, in read_tbl
    fid = open(fname, 'r')
IOError: [Errno 2] No such file or directory: 'data/skiptest.csv'
]]></error></testcase><testcase classname="pyvter.tests.test_df_read_tbl.Test_read_tbl" name="test01" time="0.000"></testcase><testcase classname="pyvter.tests.test_df_read_tbl.Test_read_tbl" name="test03" time="0.000"></testcase><testcase classname="pyvter.tests.test_df_read_tbl.Test_read_tbl" name="test04" time="0.000"></testcase><testcase classname="pyvter.tests.test_df_read_tbl.Test_read_tbl" name="test05" time="0.000"><error type="exceptions.TypeError" message="unhashable type: 'MaskedConstant'"><![CDATA[Traceback (most recent call last):
  File "/usr/lib/python2.7/unittest/case.py", line 329, in run
    testMethod()
  File "/home/jhd/Documents/Projects/pyvter/tests/test_df_read_tbl.py", line 152, in test05
    self.df.read_tbl('test.csv',skip=1,labels=True)
  File "/home/jhd/Documents/Projects/pyvter/base.py", line 264, in read_tbl
    self.__setitem__(k, v, mask[k])
  File "/home/jhd/Documents/Projects/pyvter/base.py", line 339, in __setitem__
    self.conditions[key] = self[key]
  File "/home/jhd/.local/share/virtualenvs/pyvter-QwCYsgP0/local/lib/python2.7/site-packages/dictset.py", line 538, in __setitem__
    super(DictSet, self).__setitem__(k, set(v))
TypeError: unhashable type: 'MaskedConstant'
]]></error></testcase><testcase classname="pyvter.tests.test_df_read_tbl.Test_read_tbl" name="test06" time="0.000"><error type="exceptions.TypeError" message="unhashable type: 'MaskedConstant'"><![CDATA[Traceback (most recent call last):
  File "/usr/lib/python2.7/unittest/case.py", line 329, in run
    testMethod()
  File "/home/jhd/Documents/Projects/pyvter/tests/test_df_read_tbl.py", line 175, in test06
    self.df.read_tbl('test.csv',skip=1,labels=True)
  File "/home/jhd/Documents/Projects/pyvter/base.py", line 264, in read_tbl
    self.__setitem__(k, v, mask[k])
  File "/home/jhd/Documents/Projects/pyvter/base.py", line 339, in __setitem__
    self.conditions[key] = self[key]
  File "/home/jhd/.local/share/virtualenvs/pyvter-QwCYsgP0/local/lib/python2.7/site-packages/dictset.py", line 538, in __setitem__
    super(DictSet, self).__setitem__(k, set(v))
TypeError: unhashable type: 'MaskedConstant'
]]></error></testcase><testcase classname="pyvter.tests.test_df_read_tbl.Test_read_tbl" name="test07" time="0.000"><error type="exceptions.TypeError" message="unhashable type: 'MaskedConstant'"><![CDATA[Traceback (most recent call last):
  File "/usr/lib/python2.7/unittest/case.py", line 329, in run
    testMethod()
  File "/home/jhd/Documents/Projects/pyvter/tests/test_df_read_tbl.py", line 191, in test07
    self.df.read_tbl('test.csv',skip=1,labels=True)
  File "/home/jhd/Documents/Projects/pyvter/base.py", line 264, in read_tbl
    self.__setitem__(k, v, mask[k])
  File "/home/jhd/Documents/Projects/pyvter/base.py", line 339, in __setitem__
    self.conditions[key] = self[key]
  File "/home/jhd/.local/share/virtualenvs/pyvter-QwCYsgP0/local/lib/python2.7/site-packages/dictset.py", line 538, in __setitem__
    super(DictSet, self).__setitem__(k, set(v))
TypeError: unhashable type: 'MaskedConstant'
]]></error></testcase><testcase classname="pyvter.tests.test_df_select_col.Test_writeTable" name="test0" time="0.000"><error type="exceptions.IOError" message="[Errno 2] No such file or directory: 'data/suppression~subjectXgroupXageXcycleXphase.csv'"><![CDATA[Traceback (most recent call last):
  File "/usr/lib/python2.7/unittest/case.py", line 320, in run
    self.setUp()
  File "/home/jhd/Documents/Projects/pyvter/tests/test_df_select_col.py", line 28, in setUp
    self.df.read_tbl('data/suppression~subjectXgroupXageXcycleXphase.csv')
  File "/home/jhd/Documents/Projects/pyvter/base.py", line 199, in read_tbl
    fid = open(fname, 'r')
IOError: [Errno 2] No such file or directory: 'data/suppression~subjectXgroupXageXcycleXphase.csv'
]]></error></testcase><testcase classname="pyvter.tests.test_df_select_col.Test_writeTable" name="test1" time="0.000"><error type="exceptions.IOError" message="[Errno 2] No such file or directory: 'data/suppression~subjectXgroupXageXcycleXphase.csv'"><![CDATA[Traceback (most recent call last):
  File "/usr/lib/python2.7/unittest/case.py", line 320, in run
    self.setUp()
  File "/home/jhd/Documents/Projects/pyvter/tests/test_df_select_col.py", line 28, in setUp
    self.df.read_tbl('data/suppression~subjectXgroupXageXcycleXphase.csv')
  File "/home/jhd/Documents/Projects/pyvter/base.py", line 199, in read_tbl
    fid = open(fname, 'r')
IOError: [Errno 2] No such file or directory: 'data/suppression~subjectXgroupXageXcycleXphase.csv'
]]></error></testcase><testcase classname="pyvter.tests.test_df_sort.Test_sort" name="test0" time="0.001"></testcase><testcase classname="pyvter.tests.test_df_sort.Test_sort" name="test1" time="0.001"></testcase><testcase classname="pyvter.tests.test_df_sort.Test_sort" name="test2" time="0.002"></testcase><testcase classname="pyvter.tests.test_df_sort.Test_sort" name="test3" time="0.000"></testcase><testcase classname="pyvter.tests.test_df_sort.Test_sort" name="test4" time="0.000"></testcase><testcase classname="pyvter.tests.test_df_sort.Test_sort" name="test5" time="0.000"></testcase><testcase classname="pyvter.tests.test_df_validate.Test_validate_for_failure" name="test3" time="0.000"></testcase><testcase classname="pyvter.tests.test_df_validate.Test_validate_for_failure" name="test4" time="0.000"></testcase><testcase classname="pyvter.tests.test_df_validate.Test_validate_for_success" name="test0" time="0.000"><error type="exceptions.IOError" message="[Errno 2] No such file or directory: 'data\\suppression~subjectXgroupXageXcycleXphase.csv'"><![CDATA[Traceback (most recent call last):
  File "/usr/lib/python2.7/unittest/case.py", line 329, in run
    testMethod()
  File "/home/jhd/Documents/Projects/pyvter/tests/test_df_validate.py", line 26, in test0
    df.read_tbl('data\suppression~subjectXgroupXageXcycleXphase.csv')
  File "/home/jhd/Documents/Projects/pyvter/base.py", line 199, in read_tbl
    fid = open(fname, 'r')
IOError: [Errno 2] No such file or directory: 'data\\suppression~subjectXgroupXageXcycleXphase.csv'
]]></error></testcase><testcase classname="pyvter.tests.test_df_validate.Test_validate_for_success" name="test1" time="0.000"><error type="exceptions.IOError" message="[Errno 2] No such file or directory: 'data\\suppression~subjectXgroupXageXcycleXphase.csv'"><![CDATA[Traceback (most recent call last):
  File "/usr/lib/python2.7/unittest/case.py", line 329, in run
    testMethod()
  File "/home/jhd/Documents/Projects/pyvter/tests/test_df_validate.py", line 40, in test1
    df.read_tbl('data\suppression~subjectXgroupXageXcycleXphase.csv')
  File "/home/jhd/Documents/Projects/pyvter/base.py", line 199, in read_tbl
    fid = open(fname, 'r')
IOError: [Errno 2] No such file or directory: 'data\\suppression~subjectXgroupXageXcycleXphase.csv'
]]></error></testcase><testcase classname="pyvter.tests.test_df_validate.Test_validate_for_success" name="test2" time="0.000"><error type="exceptions.IOError" message="[Errno 2] No such file or directory: 'data\\suppression~subjectXgroupXageXcycleXphase.csv'"><![CDATA[Traceback (most recent call last):
  File "/usr/lib/python2.7/unittest/case.py", line 329, in run
    testMethod()
  File "/home/jhd/Documents/Projects/pyvter/tests/test_df_validate.py", line 53, in test2
    df.read_tbl('data\suppression~subjectXgroupXageXcycleXphase.csv')
  File "/home/jhd/Documents/Projects/pyvter/base.py", line 199, in read_tbl
    fid = open(fname, 'r')
IOError: [Errno 2] No such file or directory: 'data\\suppression~subjectXgroupXageXcycleXphase.csv'
]]></error></testcase><testcase classname="pyvter.tests.test_df_where.Test_where" name="test0" time="0.000"><error type="exceptions.IOError" message="[Errno 2] No such file or directory: 'data/error~subjectXtimeofdayXcourseXmodel_MISSING.csv'"><![CDATA[Traceback (most recent call last):
  File "/usr/lib/python2.7/unittest/case.py", line 329, in run
    testMethod()
  File "/home/jhd/Documents/Projects/pyvter/tests/test_df_where.py", line 33, in test0
    df.read_tbl('data/error~subjectXtimeofdayXcourseXmodel_MISSING.csv')
  File "/home/jhd/Documents/Projects/pyvter/base.py", line 199, in read_tbl
    fid = open(fname, 'r')
IOError: [Errno 2] No such file or directory: 'data/error~subjectXtimeofdayXcourseXmodel_MISSING.csv'
]]></error></testcase><testcase classname="pyvter.tests.test_df_where.Test_where" name="test1" time="0.000"><error type="exceptions.IOError" message="[Errno 2] No such file or directory: 'data/error~subjectXtimeofdayXcourseXmodel_MISSING.csv'"><![CDATA[Traceback (most recent call last):
  File "/usr/lib/python2.7/unittest/case.py", line 329, in run
    testMethod()
  File "/home/jhd/Documents/Projects/pyvter/tests/test_df_where.py", line 44, in test1
    df.read_tbl('data/error~subjectXtimeofdayXcourseXmodel_MISSING.csv')
  File "/home/jhd/Documents/Projects/pyvter/base.py", line 199, in read_tbl
    fid = open(fname, 'r')
IOError: [Errno 2] No such file or directory: 'data/error~subjectXtimeofdayXcourseXmodel_MISSING.csv'
]]></error></testcase><testcase classname="pyvter.tests.test_df_where.Test_where" name="test2" time="0.000"><error type="exceptions.IOError" message="[Errno 2] No such file or directory: 'data/error~subjectXtimeofdayXcourseXmodel_MISSING.csv'"><![CDATA[Traceback (most recent call last):
  File "/usr/lib/python2.7/unittest/case.py", line 329, in run
    testMethod()
  File "/home/jhd/Documents/Projects/pyvter/tests/test_df_where.py", line 51, in test2
    df.read_tbl('data/error~subjectXtimeofdayXcourseXmodel_MISSING.csv')
  File "/home/jhd/Documents/Projects/pyvter/base.py", line 199, in read_tbl
    fid = open(fname, 'r')
IOError: [Errno 2] No such file or directory: 'data/error~subjectXtimeofdayXcourseXmodel_MISSING.csv'
]]></error></testcase><testcase classname="pyvter.tests.test_df_where.Test_where" name="test3" time="0.000"><error type="exceptions.IOError" message="[Errno 2] No such file or directory: 'data/error~subjectXtimeofdayXcourseXmodel_MISSING.csv'"><![CDATA[Traceback (most recent call last):
  File "/usr/lib/python2.7/unittest/case.py", line 329, in run
    testMethod()
  File "/home/jhd/Documents/Projects/pyvter/tests/test_df_where.py", line 59, in test3
    df.read_tbl('data/error~subjectXtimeofdayXcourseXmodel_MISSING.csv')
  File "/home/jhd/Documents/Projects/pyvter/base.py", line 199, in read_tbl
    fid = open(fname, 'r')
IOError: [Errno 2] No such file or directory: 'data/error~subjectXtimeofdayXcourseXmodel_MISSING.csv'
]]></error></testcase><testcase classname="pyvter.tests.test_df_where.Test_where" name="test5" time="0.001"><error type="exceptions.IOError" message="[Errno 2] No such file or directory: 'data/error~subjectXtimeofdayXcourseXmodel_MISSING.csv'"><![CDATA[Traceback (most recent call last):
  File "/usr/lib/python2.7/unittest/case.py", line 329, in run
    testMethod()
  File "/home/jhd/Documents/Projects/pyvter/tests/test_df_where.py", line 66, in test5
    df.read_tbl('data/error~subjectXtimeofdayXcourseXmodel_MISSING.csv')
  File "/home/jhd/Documents/Projects/pyvter/base.py", line 199, in read_tbl
    fid = open(fname, 'r')
IOError: [Errno 2] No such file or directory: 'data/error~subjectXtimeofdayXcourseXmodel_MISSING.csv'
]]></error></testcase><testcase classname="pyvter.tests.test_df_where.Test_where" name="test6" time="0.000"><error type="exceptions.IOError" message="[Errno 2] No such file or directory: 'data/error~subjectXtimeofdayXcourseXmodel_MISSING.csv'"><![CDATA[Traceback (most recent call last):
  File "/usr/lib/python2.7/unittest/case.py", line 329, in run
    testMethod()
  File "/home/jhd/Documents/Projects/pyvter/tests/test_df_where.py", line 74, in test6
    df.read_tbl('data/error~subjectXtimeofdayXcourseXmodel_MISSING.csv')
  File "/home/jhd/Documents/Projects/pyvter/base.py", line 199, in read_tbl
    fid = open(fname, 'r')
IOError: [Errno 2] No such file or directory: 'data/error~subjectXtimeofdayXcourseXmodel_MISSING.csv'
]]></error></testcase><testcase classname="pyvter.tests.test_df_where_update.Test_where_update" name="test0" time="0.000"><error type="exceptions.IOError" message="[Errno 2] No such file or directory: 'data/error~subjectXtimeofdayXcourseXmodel_MISSING.csv'"><![CDATA[Traceback (most recent call last):
  File "/usr/lib/python2.7/unittest/case.py", line 329, in run
    testMethod()
  File "/home/jhd/Documents/Projects/pyvter/tests/test_df_where_update.py", line 29, in test0
    df.read_tbl('data/error~subjectXtimeofdayXcourseXmodel_MISSING.csv')
  File "/home/jhd/Documents/Projects/pyvter/base.py", line 199, in read_tbl
    fid = open(fname, 'r')
IOError: [Errno 2] No such file or directory: 'data/error~subjectXtimeofdayXcourseXmodel_MISSING.csv'
]]></error></testcase><testcase classname="pyvter.tests.test_df_where_update.Test_where_update" name="test1" time="0.000"><error type="exceptions.IOError" message="[Errno 2] No such file or directory: 'data/error~subjectXtimeofdayXcourseXmodel_MISSING.csv'"><![CDATA[Traceback (most recent call last):
  File "/usr/lib/python2.7/unittest/case.py", line 329, in run
    testMethod()
  File "/home/jhd/Documents/Projects/pyvter/tests/test_df_where_update.py", line 37, in test1
    df.read_tbl('data/error~subjectXtimeofdayXcourseXmodel_MISSING.csv')
  File "/home/jhd/Documents/Projects/pyvter/base.py", line 199, in read_tbl
    fid = open(fname, 'r')
IOError: [Errno 2] No such file or directory: 'data/error~subjectXtimeofdayXcourseXmodel_MISSING.csv'
]]></error></testcase><testcase classname="pyvter.tests.test_df_where_update.Test_where_update" name="test2" time="0.000"><error type="exceptions.IOError" message="[Errno 2] No such file or directory: 'data/error~subjectXtimeofdayXcourseXmodel_MISSING.csv'"><![CDATA[Traceback (most recent call last):
  File "/usr/lib/python2.7/unittest/case.py", line 329, in run
    testMethod()
  File "/home/jhd/Documents/Projects/pyvter/tests/test_df_where_update.py", line 45, in test2
    df.read_tbl('data/error~subjectXtimeofdayXcourseXmodel_MISSING.csv')
  File "/home/jhd/Documents/Projects/pyvter/base.py", line 199, in read_tbl
    fid = open(fname, 'r')
IOError: [Errno 2] No such file or directory: 'data/error~subjectXtimeofdayXcourseXmodel_MISSING.csv'
]]></error></testcase><testcase classname="pyvter.tests.test_df_where_update.Test_where_update" name="test3" time="0.000"><error type="exceptions.IOError" message="[Errno 2] No such file or directory: 'data/error~subjectXtimeofdayXcourseXmodel_MISSING.csv'"><![CDATA[Traceback (most recent call last):
  File "/usr/lib/python2.7/unittest/case.py", line 329, in run
    testMethod()
  File "/home/jhd/Documents/Projects/pyvter/tests/test_df_where_update.py", line 53, in test3
    df.read_tbl('data/error~subjectXtimeofdayXcourseXmodel_MISSING.csv')
  File "/home/jhd/Documents/Projects/pyvter/base.py", line 199, in read_tbl
    fid = open(fname, 'r')
IOError: [Errno 2] No such file or directory: 'data/error~subjectXtimeofdayXcourseXmodel_MISSING.csv'
]]></error></testcase><testcase classname="pyvter.tests.test_df_where_update.Test_where_update" name="test5" time="0.000"><error type="exceptions.IOError" message="[Errno 2] No such file or directory: 'data/error~subjectXtimeofdayXcourseXmodel_MISSING.csv'"><![CDATA[Traceback (most recent call last):
  File "/usr/lib/python2.7/unittest/case.py", line 329, in run
    testMethod()
  File "/home/jhd/Documents/Projects/pyvter/tests/test_df_where_update.py", line 61, in test5
    df.read_tbl('data/error~subjectXtimeofdayXcourseXmodel_MISSING.csv')
  File "/home/jhd/Documents/Projects/pyvter/base.py", line 199, in read_tbl
    fid = open(fname, 'r')
IOError: [Errno 2] No such file or directory: 'data/error~subjectXtimeofdayXcourseXmodel_MISSING.csv'
]]></error></testcase><testcase classname="pyvter.tests.test_df_where_update.Test_where_update" name="test6" time="0.000"><error type="exceptions.IOError" message="[Errno 2] No such file or directory: 'data/error~subjectXtimeofdayXcourseXmodel_MISSING.csv'"><![CDATA[Traceback (most recent call last):
  File "/usr/lib/python2.7/unittest/case.py", line 329, in run
    testMethod()
  File "/home/jhd/Documents/Projects/pyvter/tests/test_df_where_update.py", line 69, in test6
    df.read_tbl('data/error~subjectXtimeofdayXcourseXmodel_MISSING.csv')
  File "/home/jhd/Documents/Projects/pyvter/base.py", line 199, in read_tbl
    fid = open(fname, 'r')
IOError: [Errno 2] No such file or directory: 'data/error~subjectXtimeofdayXcourseXmodel_MISSING.csv'
]]></error></testcase><testcase classname="pyvter.tests.test_df_write.Test_writeTable" name="test0" time="0.000"><error type="exceptions.IOError" message="[Errno 2] No such file or directory: 'data\\suppression~subjectXgroupXageXcycleXphase.csv'"><![CDATA[Traceback (most recent call last):
  File "/usr/lib/python2.7/unittest/case.py", line 320, in run
    self.setUp()
  File "/home/jhd/Documents/Projects/pyvter/tests/test_df_write.py", line 28, in setUp
    self.df.read_tbl('data\suppression~subjectXgroupXageXcycleXphase.csv')
  File "/home/jhd/Documents/Projects/pyvter/base.py", line 199, in read_tbl
    fid = open(fname, 'r')
IOError: [Errno 2] No such file or directory: 'data\\suppression~subjectXgroupXageXcycleXphase.csv'
]]></error></testcase><testcase classname="pyvter.tests.test_df_write.Test_writeTable" name="test1" time="0.000"><error type="exceptions.IOError" message="[Errno 2] No such file or directory: 'data\\suppression~subjectXgroupXageXcycleXphase.csv'"><![CDATA[Traceback (most recent call last):
  File "/usr/lib/python2.7/unittest/case.py", line 320, in run
    self.setUp()
  File "/home/jhd/Documents/Projects/pyvter/tests/test_df_write.py", line 28, in setUp
    self.df.read_tbl('data\suppression~subjectXgroupXageXcycleXphase.csv')
  File "/home/jhd/Documents/Projects/pyvter/base.py", line 199, in read_tbl
    fid = open(fname, 'r')
IOError: [Errno 2] No such file or directory: 'data\\suppression~subjectXgroupXageXcycleXphase.csv'
]]></error></testcase><testcase classname="pyvter.tests.test_plotting_box_plot.Test_box_plot" name="test0" time="0.000"><error type="exceptions.IOError" message="[Errno 2] No such file or directory: 'data/words~ageXcondition.csv'"><![CDATA[Traceback (most recent call last):
  File "/usr/lib/python2.7/unittest/case.py", line 329, in run
    testMethod()
  File "/home/jhd/Documents/Projects/pyvter/tests/test_plotting_box_plot.py", line 45, in test0
    df.read_tbl('data/words~ageXcondition.csv')
  File "/home/jhd/Documents/Projects/pyvter/base.py", line 199, in read_tbl
    fid = open(fname, 'r')
IOError: [Errno 2] No such file or directory: 'data/words~ageXcondition.csv'
]]></error></testcase><testcase classname="pyvter.tests.test_plotting_box_plot.Test_box_plot" name="test1" time="0.000"><error type="exceptions.IOError" message="[Errno 2] No such file or directory: 'data/words~ageXcondition.csv'"><![CDATA[Traceback (most recent call last):
  File "/usr/lib/python2.7/unittest/case.py", line 329, in run
    testMethod()
  File "/home/jhd/Documents/Projects/pyvter/tests/test_plotting_box_plot.py", line 73, in test1
    df.read_tbl('data/words~ageXcondition.csv')
  File "/home/jhd/Documents/Projects/pyvter/base.py", line 199, in read_tbl
    fid = open(fname, 'r')
IOError: [Errno 2] No such file or directory: 'data/words~ageXcondition.csv'
]]></error></testcase><testcase classname="pyvter.tests.test_plotting_box_plot.Test_box_plot" name="test2" time="0.000"><error type="exceptions.IOError" message="[Errno 2] No such file or directory: 'data/words~ageXcondition.csv'"><![CDATA[Traceback (most recent call last):
  File "/usr/lib/python2.7/unittest/case.py", line 329, in run
    testMethod()
  File "/home/jhd/Documents/Projects/pyvter/tests/test_plotting_box_plot.py", line 110, in test2
    df.read_tbl('data/words~ageXcondition.csv')
  File "/home/jhd/Documents/Projects/pyvter/base.py", line 199, in read_tbl
    fid = open(fname, 'r')
IOError: [Errno 2] No such file or directory: 'data/words~ageXcondition.csv'
]]></error></testcase><testcase classname="pyvter.tests.test_plotting_box_plot.Test_box_plot" name="test3" time="0.000"></testcase><testcase classname="pyvter.tests.test_plotting_box_plot.Test_box_plot" name="test4" time="0.000"></testcase><testcase classname="pyvter.tests.test_plotting_box_plot.Test_box_plot" name="test5" time="0.000"></testcase><testcase classname="pyvter.tests.test_plotting_box_plot.Test_box_plot" name="test6" time="0.000"></testcase><testcase classname="pyvter.tests.test_plotting_histogram_plot.Test_plotHist" name="test0" time="0.000"><error type="exceptions.IOError" message="[Errno 2] No such file or directory: 'data/words~ageXcondition.csv'"><![CDATA[Traceback (most recent call last):
  File "/usr/lib/python2.7/unittest/case.py", line 329, in run
    testMethod()
  File "/home/jhd/Documents/Projects/pyvter/tests/test_plotting_histogram_plot.py", line 31, in test0
    df.read_tbl('data/words~ageXcondition.csv')
  File "/home/jhd/Documents/Projects/pyvter/base.py", line 199, in read_tbl
    fid = open(fname, 'r')
IOError: [Errno 2] No such file or directory: 'data/words~ageXcondition.csv'
]]></error></testcase><testcase classname="pyvter.tests.test_plotting_histogram_plot.Test_plotHist" name="test1" time="0.000"><error type="exceptions.IOError" message="[Errno 2] No such file or directory: 'data/words~ageXcondition.csv'"><![CDATA[Traceback (most recent call last):
  File "/usr/lib/python2.7/unittest/case.py", line 329, in run
    testMethod()
  File "/home/jhd/Documents/Projects/pyvter/tests/test_plotting_histogram_plot.py", line 46, in test1
    df.read_tbl('data/words~ageXcondition.csv')
  File "/home/jhd/Documents/Projects/pyvter/base.py", line 199, in read_tbl
    fid = open(fname, 'r')
IOError: [Errno 2] No such file or directory: 'data/words~ageXcondition.csv'
]]></error></testcase><testcase classname="pyvter.tests.test_plotting_interaction_plot.Test_interaction_plot" name="test0" time="0.000"><error type="exceptions.IOError" message="[Errno 2] No such file or directory: 'data/words~ageXcondition.csv'"><![CDATA[Traceback (most recent call last):
  File "/usr/lib/python2.7/unittest/case.py", line 329, in run
    testMethod()
  File "/home/jhd/Documents/Projects/pyvter/tests/test_plotting_interaction_plot.py", line 50, in test0
    df.read_tbl('data/words~ageXcondition.csv')
  File "/home/jhd/Documents/Projects/pyvter/base.py", line 199, in read_tbl
    fid = open(fname, 'r')
IOError: [Errno 2] No such file or directory: 'data/words~ageXcondition.csv'
]]></error></testcase><testcase classname="pyvter.tests.test_plotting_interaction_plot.Test_interaction_plot" name="test01" time="0.000"><error type="exceptions.IOError" message="[Errno 2] No such file or directory: 'data/words~ageXcondition.csv'"><![CDATA[Traceback (most recent call last):
  File "/usr/lib/python2.7/unittest/case.py", line 329, in run
    testMethod()
  File "/home/jhd/Documents/Projects/pyvter/tests/test_plotting_interaction_plot.py", line 99, in test01
    df.read_tbl('data/words~ageXcondition.csv')
  File "/home/jhd/Documents/Projects/pyvter/base.py", line 199, in read_tbl
    fid = open(fname, 'r')
IOError: [Errno 2] No such file or directory: 'data/words~ageXcondition.csv'
]]></error></testcase><testcase classname="pyvter.tests.test_plotting_interaction_plot.Test_interaction_plot" name="test02" time="0.000"><error type="exceptions.IOError" message="[Errno 2] No such file or directory: 'data/words~ageXcondition.csv'"><![CDATA[Traceback (most recent call last):
  File "/usr/lib/python2.7/unittest/case.py", line 329, in run
    testMethod()
  File "/home/jhd/Documents/Projects/pyvter/tests/test_plotting_interaction_plot.py", line 130, in test02
    df.read_tbl('data/words~ageXcondition.csv')
  File "/home/jhd/Documents/Projects/pyvter/base.py", line 199, in read_tbl
    fid = open(fname, 'r')
IOError: [Errno 2] No such file or directory: 'data/words~ageXcondition.csv'
]]></error></testcase><testcase classname="pyvter.tests.test_plotting_interaction_plot.Test_interaction_plot" name="test1" time="0.000"><error type="exceptions.IOError" message="[Errno 2] No such file or directory: 'data/error~subjectXtimeofdayXcourseXmodel_MISSING.csv'"><![CDATA[Traceback (most recent call last):
  File "/usr/lib/python2.7/unittest/case.py", line 329, in run
    testMethod()
  File "/home/jhd/Documents/Projects/pyvter/tests/test_plotting_interaction_plot.py", line 165, in test1
    df.read_tbl('data/error~subjectXtimeofdayXcourseXmodel_MISSING.csv')
  File "/home/jhd/Documents/Projects/pyvter/base.py", line 199, in read_tbl
    fid = open(fname, 'r')
IOError: [Errno 2] No such file or directory: 'data/error~subjectXtimeofdayXcourseXmodel_MISSING.csv'
]]></error></testcase><testcase classname="pyvter.tests.test_plotting_interaction_plot.Test_interaction_plot" name="test2" time="0.000"><error type="exceptions.IOError" message="[Errno 2] No such file or directory: 'data\\suppression~subjectXgroupXageXcycleXphase.csv'"><![CDATA[Traceback (most recent call last):
  File "/usr/lib/python2.7/unittest/case.py", line 329, in run
    testMethod()
  File "/home/jhd/Documents/Projects/pyvter/tests/test_plotting_interaction_plot.py", line 214, in test2
    df.read_tbl('data\suppression~subjectXgroupXageXcycleXphase.csv')
  File "/home/jhd/Documents/Projects/pyvter/base.py", line 199, in read_tbl
    fid = open(fname, 'r')
IOError: [Errno 2] No such file or directory: 'data\\suppression~subjectXgroupXageXcycleXphase.csv'
]]></error></testcase><testcase classname="pyvter.tests.test_plotting_interaction_plot.Test_interaction_plot" name="test3" time="0.000"><error type="exceptions.IOError" message="[Errno 2] No such file or directory: 'data\\suppression~subjectXgroupXageXcycleXphase.csv'"><![CDATA[Traceback (most recent call last):
  File "/usr/lib/python2.7/unittest/case.py", line 329, in run
    testMethod()
  File "/home/jhd/Documents/Projects/pyvter/tests/test_plotting_interaction_plot.py", line 273, in test3
    df.read_tbl('data\suppression~subjectXgroupXageXcycleXphase.csv')
  File "/home/jhd/Documents/Projects/pyvter/base.py", line 199, in read_tbl
    fid = open(fname, 'r')
IOError: [Errno 2] No such file or directory: 'data\\suppression~subjectXgroupXageXcycleXphase.csv'
]]></error></testcase><testcase classname="pyvter.tests.test_plotting_interaction_plot.Test_interaction_plot" name="test31" time="0.000"><error type="exceptions.IOError" message="[Errno 2] No such file or directory: 'data\\suppression~subjectXgroupXageXcycleXphase.csv'"><![CDATA[Traceback (most recent call last):
  File "/usr/lib/python2.7/unittest/case.py", line 329, in run
    testMethod()
  File "/home/jhd/Documents/Projects/pyvter/tests/test_plotting_interaction_plot.py", line 303, in test31
    df.read_tbl('data\suppression~subjectXgroupXageXcycleXphase.csv')
  File "/home/jhd/Documents/Projects/pyvter/base.py", line 199, in read_tbl
    fid = open(fname, 'r')
IOError: [Errno 2] No such file or directory: 'data\\suppression~subjectXgroupXageXcycleXphase.csv'
]]></error></testcase><testcase classname="pyvter.tests.test_plotting_interaction_plot.Test_interaction_plot" name="test4" time="0.000"><error type="exceptions.IOError" message="[Errno 2] No such file or directory: 'data/words~ageXcondition.csv'"><![CDATA[Traceback (most recent call last):
  File "/usr/lib/python2.7/unittest/case.py", line 329, in run
    testMethod()
  File "/home/jhd/Documents/Projects/pyvter/tests/test_plotting_interaction_plot.py", line 345, in test4
    df.read_tbl('data/words~ageXcondition.csv')
  File "/home/jhd/Documents/Projects/pyvter/base.py", line 199, in read_tbl
    fid = open(fname, 'r')
IOError: [Errno 2] No such file or directory: 'data/words~ageXcondition.csv'
]]></error></testcase><testcase classname="pyvter.tests.test_plotting_interaction_plot.Test_interaction_plot" name="test5" time="0.000"><error type="exceptions.IOError" message="[Errno 2] No such file or directory: 'data/error~subjectXtimeofdayXcourseXmodel_MISSING.csv'"><![CDATA[Traceback (most recent call last):
  File "/usr/lib/python2.7/unittest/case.py", line 329, in run
    testMethod()
  File "/home/jhd/Documents/Projects/pyvter/tests/test_plotting_interaction_plot.py", line 390, in test5
    df.read_tbl('data/error~subjectXtimeofdayXcourseXmodel_MISSING.csv')
  File "/home/jhd/Documents/Projects/pyvter/base.py", line 199, in read_tbl
    fid = open(fname, 'r')
IOError: [Errno 2] No such file or directory: 'data/error~subjectXtimeofdayXcourseXmodel_MISSING.csv'
]]></error></testcase><testcase classname="pyvter.tests.test_plotting_interaction_plot.Test_interaction_plot" name="test6" time="0.000"><error type="exceptions.IOError" message="[Errno 2] No such file or directory: 'data\\suppression~subjectXgroupXageXcycleXphase.csv'"><![CDATA[Traceback (most recent call last):
  File "/usr/lib/python2.7/unittest/case.py", line 329, in run
    testMethod()
  File "/home/jhd/Documents/Projects/pyvter/tests/test_plotting_interaction_plot.py", line 436, in test6
    df.read_tbl('data\suppression~subjectXgroupXageXcycleXphase.csv')
  File "/home/jhd/Documents/Projects/pyvter/base.py", line 199, in read_tbl
    fid = open(fname, 'r')
IOError: [Errno 2] No such file or directory: 'data\\suppression~subjectXgroupXageXcycleXphase.csv'
]]></error></testcase><testcase classname="pyvter.tests.test_plotting_interaction_plot.Test_interaction_plot" name="test7" time="0.000"><error type="exceptions.IOError" message="[Errno 2] No such file or directory: 'data\\suppression~subjectXgroupXageXcycleXphase.csv'"><![CDATA[Traceback (most recent call last):
  File "/usr/lib/python2.7/unittest/case.py", line 329, in run
    testMethod()
  File "/home/jhd/Documents/Projects/pyvter/tests/test_plotting_interaction_plot.py", line 495, in test7
    df.read_tbl('data\suppression~subjectXgroupXageXcycleXphase.csv')
  File "/home/jhd/Documents/Projects/pyvter/base.py", line 199, in read_tbl
    fid = open(fname, 'r')
IOError: [Errno 2] No such file or directory: 'data\\suppression~subjectXgroupXageXcycleXphase.csv'
]]></error></testcase><testcase classname="pyvter.tests.test_plotting_scatter_matrix.Test_scatter_matrix" name="test0" time="0.000"><error type="exceptions.IOError" message="[Errno 2] No such file or directory: 'data/iqbrainsize.txt'"><![CDATA[Traceback (most recent call last):
  File "/usr/lib/python2.7/unittest/case.py", line 320, in run
    self.setUp()
  File "/home/jhd/Documents/Projects/pyvter/tests/test_plotting_scatter_matrix.py", line 27, in setUp
    self.df.read_tbl('data/iqbrainsize.txt', delimiter='\t')
  File "/home/jhd/Documents/Projects/pyvter/base.py", line 199, in read_tbl
    fid = open(fname, 'r')
IOError: [Errno 2] No such file or directory: 'data/iqbrainsize.txt'
]]></error></testcase><testcase classname="pyvter.tests.test_plotting_scatter_matrix.Test_scatter_matrix" name="test1" time="0.000"><error type="exceptions.IOError" message="[Errno 2] No such file or directory: 'data/iqbrainsize.txt'"><![CDATA[Traceback (most recent call last):
  File "/usr/lib/python2.7/unittest/case.py", line 320, in run
    self.setUp()
  File "/home/jhd/Documents/Projects/pyvter/tests/test_plotting_scatter_matrix.py", line 27, in setUp
    self.df.read_tbl('data/iqbrainsize.txt', delimiter='\t')
  File "/home/jhd/Documents/Projects/pyvter/base.py", line 199, in read_tbl
    fid = open(fname, 'r')
IOError: [Errno 2] No such file or directory: 'data/iqbrainsize.txt'
]]></error></testcase><testcase classname="pyvter.tests.test_plotting_scatter_matrix.Test_scatter_matrix" name="test2" time="0.000"><error type="exceptions.IOError" message="[Errno 2] No such file or directory: 'data/iqbrainsize.txt'"><![CDATA[Traceback (most recent call last):
  File "/usr/lib/python2.7/unittest/case.py", line 320, in run
    self.setUp()
  File "/home/jhd/Documents/Projects/pyvter/tests/test_plotting_scatter_matrix.py", line 27, in setUp
    self.df.read_tbl('data/iqbrainsize.txt', delimiter='\t')
  File "/home/jhd/Documents/Projects/pyvter/base.py", line 199, in read_tbl
    fid = open(fname, 'r')
IOError: [Errno 2] No such file or directory: 'data/iqbrainsize.txt'
]]></error></testcase><testcase classname="pyvter.tests.test_plotting_scatter_matrix.Test_scatter_matrix" name="test3" time="0.000"><error type="exceptions.IOError" message="[Errno 2] No such file or directory: 'data/iqbrainsize.txt'"><![CDATA[Traceback (most recent call last):
  File "/usr/lib/python2.7/unittest/case.py", line 320, in run
    self.setUp()
  File "/home/jhd/Documents/Projects/pyvter/tests/test_plotting_scatter_matrix.py", line 27, in setUp
    self.df.read_tbl('data/iqbrainsize.txt', delimiter='\t')
  File "/home/jhd/Documents/Projects/pyvter/base.py", line 199, in read_tbl
    fid = open(fname, 'r')
IOError: [Errno 2] No such file or directory: 'data/iqbrainsize.txt'
]]></error></testcase><testcase classname="pyvter.tests.test_plotting_scatter_matrix.Test_scatter_matrix" name="test4" time="0.000"><error type="exceptions.IOError" message="[Errno 2] No such file or directory: 'data/iqbrainsize.txt'"><![CDATA[Traceback (most recent call last):
  File "/usr/lib/python2.7/unittest/case.py", line 320, in run
    self.setUp()
  File "/home/jhd/Documents/Projects/pyvter/tests/test_plotting_scatter_matrix.py", line 27, in setUp
    self.df.read_tbl('data/iqbrainsize.txt', delimiter='\t')
  File "/home/jhd/Documents/Projects/pyvter/base.py", line 199, in read_tbl
    fid = open(fname, 'r')
IOError: [Errno 2] No such file or directory: 'data/iqbrainsize.txt'
]]></error></testcase><testcase classname="pyvter.tests.test_plotting_scatter_matrix.Test_scatter_matrix" name="test5" time="0.000"><error type="exceptions.IOError" message="[Errno 2] No such file or directory: 'data/iqbrainsize.txt'"><![CDATA[Traceback (most recent call last):
  File "/usr/lib/python2.7/unittest/case.py", line 320, in run
    self.setUp()
  File "/home/jhd/Documents/Projects/pyvter/tests/test_plotting_scatter_matrix.py", line 27, in setUp
    self.df.read_tbl('data/iqbrainsize.txt', delimiter='\t')
  File "/home/jhd/Documents/Projects/pyvter/base.py", line 199, in read_tbl
    fid = open(fname, 'r')
IOError: [Errno 2] No such file or directory: 'data/iqbrainsize.txt'
]]></error></testcase><testcase classname="pyvter.tests.test_plotting_scatter_matrix.Test_scatter_matrix" name="test6" time="0.000"><error type="exceptions.IOError" message="[Errno 2] No such file or directory: 'data/iqbrainsize.txt'"><![CDATA[Traceback (most recent call last):
  File "/usr/lib/python2.7/unittest/case.py", line 320, in run
    self.setUp()
  File "/home/jhd/Documents/Projects/pyvter/tests/test_plotting_scatter_matrix.py", line 27, in setUp
    self.df.read_tbl('data/iqbrainsize.txt', delimiter='\t')
  File "/home/jhd/Documents/Projects/pyvter/base.py", line 199, in read_tbl
    fid = open(fname, 'r')
IOError: [Errno 2] No such file or directory: 'data/iqbrainsize.txt'
]]></error></testcase><testcase classname="pyvter.tests.test_plotting_scatter_plot.Test_scatter_plot" name="test01" time="0.000"><error type="exceptions.IOError" message="[Errno 2] No such file or directory: 'data/iqbrainsize.txt'"><![CDATA[Traceback (most recent call last):
  File "/usr/lib/python2.7/unittest/case.py", line 329, in run
    testMethod()
  File "/home/jhd/Documents/Projects/pyvter/tests/test_plotting_scatter_plot.py", line 28, in test01
    df.read_tbl('data/iqbrainsize.txt', delimiter='\t')
  File "/home/jhd/Documents/Projects/pyvter/base.py", line 199, in read_tbl
    fid = open(fname, 'r')
IOError: [Errno 2] No such file or directory: 'data/iqbrainsize.txt'
]]></error></testcase><testcase classname="pyvter.tests.test_plotting_scatter_plot.Test_scatter_plot" name="test02" time="0.000"><error type="exceptions.IOError" message="[Errno 2] No such file or directory: 'data/iqbrainsize.txt'"><![CDATA[Traceback (most recent call last):
  File "/usr/lib/python2.7/unittest/case.py", line 329, in run
    testMethod()
  File "/home/jhd/Documents/Projects/pyvter/tests/test_plotting_scatter_plot.py", line 37, in test02
    df.read_tbl('data/iqbrainsize.txt', delimiter='\t')
  File "/home/jhd/Documents/Projects/pyvter/base.py", line 199, in read_tbl
    fid = open(fname, 'r')
IOError: [Errno 2] No such file or directory: 'data/iqbrainsize.txt'
]]></error></testcase><testcase classname="pyvter.tests.test_pt__getitem__.Test_pt__getitem__" name="test0" time="0.000"><error type="exceptions.IOError" message="[Errno 2] No such file or directory: 'data/error~subjectXtimeofdayXcourseXmodel_MISSING.csv'"><![CDATA[Traceback (most recent call last):
  File "/usr/lib/python2.7/unittest/case.py", line 329, in run
    testMethod()
  File "/home/jhd/Documents/Projects/pyvter/tests/test_pt__getitem__.py", line 28, in test0
    df.read_tbl('data/error~subjectXtimeofdayXcourseXmodel_MISSING.csv')
  File "/home/jhd/Documents/Projects/pyvter/base.py", line 199, in read_tbl
    fid = open(fname, 'r')
IOError: [Errno 2] No such file or directory: 'data/error~subjectXtimeofdayXcourseXmodel_MISSING.csv'
]]></error></testcase><testcase classname="pyvter.tests.test_pt__getitem__.Test_pt__getitem__" name="test1" time="0.000"><error type="exceptions.IOError" message="[Errno 2] No such file or directory: 'data/error~subjectXtimeofdayXcourseXmodel_MISSING.csv'"><![CDATA[Traceback (most recent call last):
  File "/usr/lib/python2.7/unittest/case.py", line 329, in run
    testMethod()
  File "/home/jhd/Documents/Projects/pyvter/tests/test_pt__getitem__.py", line 43, in test1
    df.read_tbl('data/error~subjectXtimeofdayXcourseXmodel_MISSING.csv')
  File "/home/jhd/Documents/Projects/pyvter/base.py", line 199, in read_tbl
    fid = open(fname, 'r')
IOError: [Errno 2] No such file or directory: 'data/error~subjectXtimeofdayXcourseXmodel_MISSING.csv'
]]></error></testcase><testcase classname="pyvter.tests.test_pt__getitem__.Test_pt__getitem__" name="test2" time="0.000"><error type="exceptions.IOError" message="[Errno 2] No such file or directory: 'data/error~subjectXtimeofdayXcourseXmodel_MISSING.csv'"><![CDATA[Traceback (most recent call last):
  File "/usr/lib/python2.7/unittest/case.py", line 329, in run
    testMethod()
  File "/home/jhd/Documents/Projects/pyvter/tests/test_pt__getitem__.py", line 58, in test2
    df.read_tbl('data/error~subjectXtimeofdayXcourseXmodel_MISSING.csv')
  File "/home/jhd/Documents/Projects/pyvter/base.py", line 199, in read_tbl
    fid = open(fname, 'r')
IOError: [Errno 2] No such file or directory: 'data/error~subjectXtimeofdayXcourseXmodel_MISSING.csv'
]]></error></testcase><testcase classname="pyvter.tests.test_pt__getitem__.Test_pt__getitem__" name="test3" time="0.000"><error type="exceptions.IOError" message="[Errno 2] No such file or directory: 'data/error~subjectXtimeofdayXcourseXmodel_MISSING.csv'"><![CDATA[Traceback (most recent call last):
  File "/usr/lib/python2.7/unittest/case.py", line 329, in run
    testMethod()
  File "/home/jhd/Documents/Projects/pyvter/tests/test_pt__getitem__.py", line 73, in test3
    df.read_tbl('data/error~subjectXtimeofdayXcourseXmodel_MISSING.csv')
  File "/home/jhd/Documents/Projects/pyvter/base.py", line 199, in read_tbl
    fid = open(fname, 'r')
IOError: [Errno 2] No such file or directory: 'data/error~subjectXtimeofdayXcourseXmodel_MISSING.csv'
]]></error></testcase><testcase classname="pyvter.tests.test_pt__getitem__.Test_pt__getitem__" name="test4" time="0.000"><error type="exceptions.IOError" message="[Errno 2] No such file or directory: 'data/error~subjectXtimeofdayXcourseXmodel_MISSING.csv'"><![CDATA[Traceback (most recent call last):
  File "/usr/lib/python2.7/unittest/case.py", line 329, in run
    testMethod()
  File "/home/jhd/Documents/Projects/pyvter/tests/test_pt__getitem__.py", line 88, in test4
    df.read_tbl('data/error~subjectXtimeofdayXcourseXmodel_MISSING.csv')
  File "/home/jhd/Documents/Projects/pyvter/base.py", line 199, in read_tbl
    fid = open(fname, 'r')
IOError: [Errno 2] No such file or directory: 'data/error~subjectXtimeofdayXcourseXmodel_MISSING.csv'
]]></error></testcase><testcase classname="pyvter.tests.test_pt__getitem__.Test_pt__getitem__" name="test5" time="0.000"><error type="exceptions.IOError" message="[Errno 2] No such file or directory: 'data/error~subjectXtimeofdayXcourseXmodel_MISSING.csv'"><![CDATA[Traceback (most recent call last):
  File "/usr/lib/python2.7/unittest/case.py", line 329, in run
    testMethod()
  File "/home/jhd/Documents/Projects/pyvter/tests/test_pt__getitem__.py", line 104, in test5
    df.read_tbl('data/error~subjectXtimeofdayXcourseXmodel_MISSING.csv')
  File "/home/jhd/Documents/Projects/pyvter/base.py", line 199, in read_tbl
    fid = open(fname, 'r')
IOError: [Errno 2] No such file or directory: 'data/error~subjectXtimeofdayXcourseXmodel_MISSING.csv'
]]></error></testcase><testcase classname="pyvter.tests.test_pt__getitem__.Test_pt__getitem__" name="test6" time="0.000"><error type="exceptions.IOError" message="[Errno 2] No such file or directory: 'data/error~subjectXtimeofdayXcourseXmodel_MISSING.csv'"><![CDATA[Traceback (most recent call last):
  File "/usr/lib/python2.7/unittest/case.py", line 329, in run
    testMethod()
  File "/home/jhd/Documents/Projects/pyvter/tests/test_pt__getitem__.py", line 119, in test6
    df.read_tbl('data/error~subjectXtimeofdayXcourseXmodel_MISSING.csv')
  File "/home/jhd/Documents/Projects/pyvter/base.py", line 199, in read_tbl
    fid = open(fname, 'r')
IOError: [Errno 2] No such file or directory: 'data/error~subjectXtimeofdayXcourseXmodel_MISSING.csv'
]]></error></testcase><testcase classname="pyvter.tests.test_pt__getitem__.Test_pt__getitem__" name="test7" time="0.000"><error type="exceptions.IOError" message="[Errno 2] No such file or directory: 'data/error~subjectXtimeofdayXcourseXmodel_MISSING.csv'"><![CDATA[Traceback (most recent call last):
  File "/usr/lib/python2.7/unittest/case.py", line 329, in run
    testMethod()
  File "/home/jhd/Documents/Projects/pyvter/tests/test_pt__getitem__.py", line 133, in test7
    df.read_tbl('data/error~subjectXtimeofdayXcourseXmodel_MISSING.csv')
  File "/home/jhd/Documents/Projects/pyvter/base.py", line 199, in read_tbl
    fid = open(fname, 'r')
IOError: [Errno 2] No such file or directory: 'data/error~subjectXtimeofdayXcourseXmodel_MISSING.csv'
]]></error></testcase><testcase classname="pyvter.tests.test_pt__repr__.Test_pt__repr__" name="test0" time="0.000"><error type="exceptions.IOError" message="[Errno 2] No such file or directory: 'data/error~subjectXtimeofdayXcourseXmodel_MISSING.csv'"><![CDATA[Traceback (most recent call last):
  File "/usr/lib/python2.7/unittest/case.py", line 329, in run
    testMethod()
  File "/home/jhd/Documents/Projects/pyvter/tests/test_pt__repr__.py", line 30, in test0
    df.read_tbl('data/error~subjectXtimeofdayXcourseXmodel_MISSING.csv')
  File "/home/jhd/Documents/Projects/pyvter/base.py", line 199, in read_tbl
    fid = open(fname, 'r')
IOError: [Errno 2] No such file or directory: 'data/error~subjectXtimeofdayXcourseXmodel_MISSING.csv'
]]></error></testcase><testcase classname="pyvter.tests.test_pt__repr__.Test_pt__repr__" name="test1" time="0.000"><error type="exceptions.IOError" message="[Errno 2] No such file or directory: 'data/error~subjectXtimeofdayXcourseXmodel_MISSING.csv'"><![CDATA[Traceback (most recent call last):
  File "/usr/lib/python2.7/unittest/case.py", line 329, in run
    testMethod()
  File "/home/jhd/Documents/Projects/pyvter/tests/test_pt__repr__.py", line 38, in test1
    df.read_tbl('data/error~subjectXtimeofdayXcourseXmodel_MISSING.csv')
  File "/home/jhd/Documents/Projects/pyvter/base.py", line 199, in read_tbl
    fid = open(fname, 'r')
IOError: [Errno 2] No such file or directory: 'data/error~subjectXtimeofdayXcourseXmodel_MISSING.csv'
]]></error></testcase><testcase classname="pyvter.tests.test_pt__repr__.Test_pt__repr__" name="test2" time="0.000"><error type="exceptions.IOError" message="[Errno 2] No such file or directory: 'data/error~subjectXtimeofdayXcourseXmodel_MISSING.csv'"><![CDATA[Traceback (most recent call last):
  File "/usr/lib/python2.7/unittest/case.py", line 329, in run
    testMethod()
  File "/home/jhd/Documents/Projects/pyvter/tests/test_pt__repr__.py", line 46, in test2
    df.read_tbl('data/error~subjectXtimeofdayXcourseXmodel_MISSING.csv')
  File "/home/jhd/Documents/Projects/pyvter/base.py", line 199, in read_tbl
    fid = open(fname, 'r')
IOError: [Errno 2] No such file or directory: 'data/error~subjectXtimeofdayXcourseXmodel_MISSING.csv'
]]></error></testcase><testcase classname="pyvter.tests.test_pt__setitem__.Test_pt__setitem__" name="test0" time="0.000"><error type="exceptions.IOError" message="[Errno 2] No such file or directory: 'data/error~subjectXtimeofdayXcourseXmodel_MISSING.csv'"><![CDATA[Traceback (most recent call last):
  File "/usr/lib/python2.7/unittest/case.py", line 329, in run
    testMethod()
  File "/home/jhd/Documents/Projects/pyvter/tests/test_pt__setitem__.py", line 36, in test0
    df.read_tbl('data/error~subjectXtimeofdayXcourseXmodel_MISSING.csv')
  File "/home/jhd/Documents/Projects/pyvter/base.py", line 199, in read_tbl
    fid = open(fname, 'r')
IOError: [Errno 2] No such file or directory: 'data/error~subjectXtimeofdayXcourseXmodel_MISSING.csv'
]]></error></testcase><testcase classname="pyvter.tests.test_pt__setitem__.Test_pt__setitem__" name="test1" time="0.000"><error type="exceptions.IOError" message="[Errno 2] No such file or directory: 'data/error~subjectXtimeofdayXcourseXmodel_MISSING.csv'"><![CDATA[Traceback (most recent call last):
  File "/usr/lib/python2.7/unittest/case.py", line 329, in run
    testMethod()
  File "/home/jhd/Documents/Projects/pyvter/tests/test_pt__setitem__.py", line 56, in test1
    df.read_tbl('data/error~subjectXtimeofdayXcourseXmodel_MISSING.csv')
  File "/home/jhd/Documents/Projects/pyvter/base.py", line 199, in read_tbl
    fid = open(fname, 'r')
IOError: [Errno 2] No such file or directory: 'data/error~subjectXtimeofdayXcourseXmodel_MISSING.csv'
]]></error></testcase><testcase classname="pyvter.tests.test_pt__setitem__.Test_pt__setitem__" name="test2" time="0.000"><error type="exceptions.IOError" message="[Errno 2] No such file or directory: 'data/error~subjectXtimeofdayXcourseXmodel_MISSING.csv'"><![CDATA[Traceback (most recent call last):
  File "/usr/lib/python2.7/unittest/case.py", line 329, in run
    testMethod()
  File "/home/jhd/Documents/Projects/pyvter/tests/test_pt__setitem__.py", line 76, in test2
    df.read_tbl('data/error~subjectXtimeofdayXcourseXmodel_MISSING.csv')
  File "/home/jhd/Documents/Projects/pyvter/base.py", line 199, in read_tbl
    fid = open(fname, 'r')
IOError: [Errno 2] No such file or directory: 'data/error~subjectXtimeofdayXcourseXmodel_MISSING.csv'
]]></error></testcase><testcase classname="pyvter.tests.test_pt__setitem__.Test_pt__setitem__" name="test5" time="0.000"><error type="exceptions.IOError" message="[Errno 2] No such file or directory: 'data/error~subjectXtimeofdayXcourseXmodel_MISSING.csv'"><![CDATA[Traceback (most recent call last):
  File "/usr/lib/python2.7/unittest/case.py", line 329, in run
    testMethod()
  File "/home/jhd/Documents/Projects/pyvter/tests/test_pt__setitem__.py", line 97, in test5
    df.read_tbl('data/error~subjectXtimeofdayXcourseXmodel_MISSING.csv')
  File "/home/jhd/Documents/Projects/pyvter/base.py", line 199, in read_tbl
    fid = open(fname, 'r')
IOError: [Errno 2] No such file or directory: 'data/error~subjectXtimeofdayXcourseXmodel_MISSING.csv'
]]></error></testcase><testcase classname="pyvter.tests.test_pt__str__.Test_pivot_1" name="test0" time="0.000"><error type="exceptions.IOError" message="[Errno 2] No such file or directory: 'data/words~ageXcondition.csv'"><![CDATA[Traceback (most recent call last):
  File "/usr/lib/python2.7/unittest/case.py", line 320, in run
    self.setUp()
  File "/home/jhd/Documents/Projects/pyvter/tests/test_pt__str__.py", line 34, in setUp
    self.df.read_tbl('data/words~ageXcondition.csv')
  File "/home/jhd/Documents/Projects/pyvter/base.py", line 199, in read_tbl
    fid = open(fname, 'r')
IOError: [Errno 2] No such file or directory: 'data/words~ageXcondition.csv'
]]></error></testcase><testcase classname="pyvter.tests.test_pt__str__.Test_pivot_1" name="test10" time="0.000"><error type="exceptions.IOError" message="[Errno 2] No such file or directory: 'data/words~ageXcondition.csv'"><![CDATA[Traceback (most recent call last):
  File "/usr/lib/python2.7/unittest/case.py", line 320, in run
    self.setUp()
  File "/home/jhd/Documents/Projects/pyvter/tests/test_pt__str__.py", line 34, in setUp
    self.df.read_tbl('data/words~ageXcondition.csv')
  File "/home/jhd/Documents/Projects/pyvter/base.py", line 199, in read_tbl
    fid = open(fname, 'r')
IOError: [Errno 2] No such file or directory: 'data/words~ageXcondition.csv'
]]></error></testcase><testcase classname="pyvter.tests.test_pt__str__.Test_pivot_1" name="test11" time="0.000"><error type="exceptions.IOError" message="[Errno 2] No such file or directory: 'data/words~ageXcondition.csv'"><![CDATA[Traceback (most recent call last):
  File "/usr/lib/python2.7/unittest/case.py", line 320, in run
    self.setUp()
  File "/home/jhd/Documents/Projects/pyvter/tests/test_pt__str__.py", line 34, in setUp
    self.df.read_tbl('data/words~ageXcondition.csv')
  File "/home/jhd/Documents/Projects/pyvter/base.py", line 199, in read_tbl
    fid = open(fname, 'r')
IOError: [Errno 2] No such file or directory: 'data/words~ageXcondition.csv'
]]></error></testcase><testcase classname="pyvter.tests.test_pt__str__.Test_pivot_1" name="test2" time="0.000"><error type="exceptions.IOError" message="[Errno 2] No such file or directory: 'data/words~ageXcondition.csv'"><![CDATA[Traceback (most recent call last):
  File "/usr/lib/python2.7/unittest/case.py", line 320, in run
    self.setUp()
  File "/home/jhd/Documents/Projects/pyvter/tests/test_pt__str__.py", line 34, in setUp
    self.df.read_tbl('data/words~ageXcondition.csv')
  File "/home/jhd/Documents/Projects/pyvter/base.py", line 199, in read_tbl
    fid = open(fname, 'r')
IOError: [Errno 2] No such file or directory: 'data/words~ageXcondition.csv'
]]></error></testcase><testcase classname="pyvter.tests.test_pt__str__.Test_pivot_1" name="test3" time="0.000"><error type="exceptions.IOError" message="[Errno 2] No such file or directory: 'data/words~ageXcondition.csv'"><![CDATA[Traceback (most recent call last):
  File "/usr/lib/python2.7/unittest/case.py", line 320, in run
    self.setUp()
  File "/home/jhd/Documents/Projects/pyvter/tests/test_pt__str__.py", line 34, in setUp
    self.df.read_tbl('data/words~ageXcondition.csv')
  File "/home/jhd/Documents/Projects/pyvter/base.py", line 199, in read_tbl
    fid = open(fname, 'r')
IOError: [Errno 2] No such file or directory: 'data/words~ageXcondition.csv'
]]></error></testcase><testcase classname="pyvter.tests.test_pt__str__.Test_pivot_1" name="test4" time="0.000"><error type="exceptions.IOError" message="[Errno 2] No such file or directory: 'data/words~ageXcondition.csv'"><![CDATA[Traceback (most recent call last):
  File "/usr/lib/python2.7/unittest/case.py", line 320, in run
    self.setUp()
  File "/home/jhd/Documents/Projects/pyvter/tests/test_pt__str__.py", line 34, in setUp
    self.df.read_tbl('data/words~ageXcondition.csv')
  File "/home/jhd/Documents/Projects/pyvter/base.py", line 199, in read_tbl
    fid = open(fname, 'r')
IOError: [Errno 2] No such file or directory: 'data/words~ageXcondition.csv'
]]></error></testcase><testcase classname="pyvter.tests.test_pt__str__.Test_pivot_1" name="test6" time="0.000"><error type="exceptions.IOError" message="[Errno 2] No such file or directory: 'data/words~ageXcondition.csv'"><![CDATA[Traceback (most recent call last):
  File "/usr/lib/python2.7/unittest/case.py", line 320, in run
    self.setUp()
  File "/home/jhd/Documents/Projects/pyvter/tests/test_pt__str__.py", line 34, in setUp
    self.df.read_tbl('data/words~ageXcondition.csv')
  File "/home/jhd/Documents/Projects/pyvter/base.py", line 199, in read_tbl
    fid = open(fname, 'r')
IOError: [Errno 2] No such file or directory: 'data/words~ageXcondition.csv'
]]></error></testcase><testcase classname="pyvter.tests.test_pt__str__.Test_pivot_1" name="test7" time="0.000"><error type="exceptions.IOError" message="[Errno 2] No such file or directory: 'data/words~ageXcondition.csv'"><![CDATA[Traceback (most recent call last):
  File "/usr/lib/python2.7/unittest/case.py", line 320, in run
    self.setUp()
  File "/home/jhd/Documents/Projects/pyvter/tests/test_pt__str__.py", line 34, in setUp
    self.df.read_tbl('data/words~ageXcondition.csv')
  File "/home/jhd/Documents/Projects/pyvter/base.py", line 199, in read_tbl
    fid = open(fname, 'r')
IOError: [Errno 2] No such file or directory: 'data/words~ageXcondition.csv'
]]></error></testcase><testcase classname="pyvter.tests.test_pt__str__.Test_pivot_1" name="test8" time="0.000"><error type="exceptions.IOError" message="[Errno 2] No such file or directory: 'data/words~ageXcondition.csv'"><![CDATA[Traceback (most recent call last):
  File "/usr/lib/python2.7/unittest/case.py", line 320, in run
    self.setUp()
  File "/home/jhd/Documents/Projects/pyvter/tests/test_pt__str__.py", line 34, in setUp
    self.df.read_tbl('data/words~ageXcondition.csv')
  File "/home/jhd/Documents/Projects/pyvter/base.py", line 199, in read_tbl
    fid = open(fname, 'r')
IOError: [Errno 2] No such file or directory: 'data/words~ageXcondition.csv'
]]></error></testcase><testcase classname="pyvter.tests.test_pt__str__.Test_pivot_1" name="test9" time="0.000"><error type="exceptions.IOError" message="[Errno 2] No such file or directory: 'data/words~ageXcondition.csv'"><![CDATA[Traceback (most recent call last):
  File "/usr/lib/python2.7/unittest/case.py", line 320, in run
    self.setUp()
  File "/home/jhd/Documents/Projects/pyvter/tests/test_pt__str__.py", line 34, in setUp
    self.df.read_tbl('data/words~ageXcondition.csv')
  File "/home/jhd/Documents/Projects/pyvter/base.py", line 199, in read_tbl
    fid = open(fname, 'r')
IOError: [Errno 2] No such file or directory: 'data/words~ageXcondition.csv'
]]></error></testcase><testcase classname="pyvter.tests.test_pt__str__.Test_pivot_2" name="test12" time="0.000"><error type="exceptions.IOError" message="[Errno 2] No such file or directory: 'data/words~ageXcondition.csv'"><![CDATA[Traceback (most recent call last):
  File "/usr/lib/python2.7/unittest/case.py", line 320, in run
    self.setUp()
  File "/home/jhd/Documents/Projects/pyvter/tests/test_pt__str__.py", line 219, in setUp
    self.df.read_tbl('data/words~ageXcondition.csv')
  File "/home/jhd/Documents/Projects/pyvter/base.py", line 199, in read_tbl
    fid = open(fname, 'r')
IOError: [Errno 2] No such file or directory: 'data/words~ageXcondition.csv'
]]></error></testcase><testcase classname="pyvter.tests.test_pt__str__.Test_pivot_2" name="test13" time="0.000"><error type="exceptions.IOError" message="[Errno 2] No such file or directory: 'data/words~ageXcondition.csv'"><![CDATA[Traceback (most recent call last):
  File "/usr/lib/python2.7/unittest/case.py", line 320, in run
    self.setUp()
  File "/home/jhd/Documents/Projects/pyvter/tests/test_pt__str__.py", line 219, in setUp
    self.df.read_tbl('data/words~ageXcondition.csv')
  File "/home/jhd/Documents/Projects/pyvter/base.py", line 199, in read_tbl
    fid = open(fname, 'r')
IOError: [Errno 2] No such file or directory: 'data/words~ageXcondition.csv'
]]></error></testcase><testcase classname="pyvter.tests.test_pt_flatten.Test_pt_flatten" name="test0" time="0.000"><error type="exceptions.IOError" message="[Errno 2] No such file or directory: 'data/error~subjectXtimeofdayXcourseXmodel_MISSING.csv'"><![CDATA[Traceback (most recent call last):
  File "/usr/lib/python2.7/unittest/case.py", line 329, in run
    testMethod()
  File "/home/jhd/Documents/Projects/pyvter/tests/test_pt_flatten.py", line 29, in test0
    df.read_tbl('data/error~subjectXtimeofdayXcourseXmodel_MISSING.csv')
  File "/home/jhd/Documents/Projects/pyvter/base.py", line 199, in read_tbl
    fid = open(fname, 'r')
IOError: [Errno 2] No such file or directory: 'data/error~subjectXtimeofdayXcourseXmodel_MISSING.csv'
]]></error></testcase><testcase classname="pyvter.tests.test_pt_flatten.Test_pt_flatten" name="test1" time="0.000"><error type="exceptions.IOError" message="[Errno 2] No such file or directory: 'data/error~subjectXtimeofdayXcourseXmodel_MISSING.csv'"><![CDATA[Traceback (most recent call last):
  File "/usr/lib/python2.7/unittest/case.py", line 329, in run
    testMethod()
  File "/home/jhd/Documents/Projects/pyvter/tests/test_pt_flatten.py", line 40, in test1
    df.read_tbl('data/error~subjectXtimeofdayXcourseXmodel_MISSING.csv')
  File "/home/jhd/Documents/Projects/pyvter/base.py", line 199, in read_tbl
    fid = open(fname, 'r')
IOError: [Errno 2] No such file or directory: 'data/error~subjectXtimeofdayXcourseXmodel_MISSING.csv'
]]></error></testcase><testcase classname="pyvter.tests.test_pt_flatten.Test_pt_flatten" name="test2" time="0.000"><error type="exceptions.IOError" message="[Errno 2] No such file or directory: 'data/error~subjectXtimeofdayXcourseXmodel_MISSING.csv'"><![CDATA[Traceback (most recent call last):
  File "/usr/lib/python2.7/unittest/case.py", line 329, in run
    testMethod()
  File "/home/jhd/Documents/Projects/pyvter/tests/test_pt_flatten.py", line 51, in test2
    df.read_tbl('data/error~subjectXtimeofdayXcourseXmodel_MISSING.csv')
  File "/home/jhd/Documents/Projects/pyvter/base.py", line 199, in read_tbl
    fid = open(fname, 'r')
IOError: [Errno 2] No such file or directory: 'data/error~subjectXtimeofdayXcourseXmodel_MISSING.csv'
]]></error></testcase><testcase classname="pyvter.tests.test_pt_iterators.Test_pt_mathmethods__iter__" name="test1" time="0.000"><error type="exceptions.IOError" message="[Errno 2] No such file or directory: 'data/error~subjectXtimeofdayXcourseXmodel_MISSING.csv'"><![CDATA[Traceback (most recent call last):
  File "/usr/lib/python2.7/unittest/case.py", line 329, in run
    testMethod()
  File "/home/jhd/Documents/Projects/pyvter/tests/test_pt_iterators.py", line 39, in test1
    df.read_tbl('data/error~subjectXtimeofdayXcourseXmodel_MISSING.csv')
  File "/home/jhd/Documents/Projects/pyvter/base.py", line 199, in read_tbl
    fid = open(fname, 'r')
IOError: [Errno 2] No such file or directory: 'data/error~subjectXtimeofdayXcourseXmodel_MISSING.csv'
]]></error></testcase><testcase classname="pyvter.tests.test_pt_iterators.Test_pt_mathmethods__iter__" name="test2" time="0.000"><error type="exceptions.IOError" message="[Errno 2] No such file or directory: 'data/error~subjectXtimeofdayXcourseXmodel_MISSING.csv'"><![CDATA[Traceback (most recent call last):
  File "/usr/lib/python2.7/unittest/case.py", line 329, in run
    testMethod()
  File "/home/jhd/Documents/Projects/pyvter/tests/test_pt_iterators.py", line 55, in test2
    df.read_tbl('data/error~subjectXtimeofdayXcourseXmodel_MISSING.csv')
  File "/home/jhd/Documents/Projects/pyvter/base.py", line 199, in read_tbl
    fid = open(fname, 'r')
IOError: [Errno 2] No such file or directory: 'data/error~subjectXtimeofdayXcourseXmodel_MISSING.csv'
]]></error></testcase><testcase classname="pyvter.tests.test_pt_iterators.Test_pt_mathmethods__iter__" name="test3" time="0.000"><error type="exceptions.IOError" message="[Errno 2] No such file or directory: 'data/error~subjectXtimeofdayXcourseXmodel_MISSING.csv'"><![CDATA[Traceback (most recent call last):
  File "/usr/lib/python2.7/unittest/case.py", line 329, in run
    testMethod()
  File "/home/jhd/Documents/Projects/pyvter/tests/test_pt_iterators.py", line 73, in test3
    df.read_tbl('data/error~subjectXtimeofdayXcourseXmodel_MISSING.csv')
  File "/home/jhd/Documents/Projects/pyvter/base.py", line 199, in read_tbl
    fid = open(fname, 'r')
IOError: [Errno 2] No such file or directory: 'data/error~subjectXtimeofdayXcourseXmodel_MISSING.csv'
]]></error></testcase><testcase classname="pyvter.tests.test_pt_iterators.Test_pt_mathmethods__iter__" name="test4" time="0.000"><error type="exceptions.IOError" message="[Errno 2] No such file or directory: 'data/error~subjectXtimeofdayXcourseXmodel_MISSING.csv'"><![CDATA[Traceback (most recent call last):
  File "/usr/lib/python2.7/unittest/case.py", line 329, in run
    testMethod()
  File "/home/jhd/Documents/Projects/pyvter/tests/test_pt_iterators.py", line 96, in test4
    df.read_tbl('data/error~subjectXtimeofdayXcourseXmodel_MISSING.csv')
  File "/home/jhd/Documents/Projects/pyvter/base.py", line 199, in read_tbl
    fid = open(fname, 'r')
IOError: [Errno 2] No such file or directory: 'data/error~subjectXtimeofdayXcourseXmodel_MISSING.csv'
]]></error></testcase><testcase classname="pyvter.tests.test_pt_iterators.Test_pt_mathmethods__iter__" name="test5" time="0.000"><error type="exceptions.IOError" message="[Errno 2] No such file or directory: 'data/error~subjectXtimeofdayXcourseXmodel_MISSING.csv'"><![CDATA[Traceback (most recent call last):
  File "/usr/lib/python2.7/unittest/case.py", line 329, in run
    testMethod()
  File "/home/jhd/Documents/Projects/pyvter/tests/test_pt_iterators.py", line 119, in test5
    df.read_tbl('data/error~subjectXtimeofdayXcourseXmodel_MISSING.csv')
  File "/home/jhd/Documents/Projects/pyvter/base.py", line 199, in read_tbl
    fid = open(fname, 'r')
IOError: [Errno 2] No such file or directory: 'data/error~subjectXtimeofdayXcourseXmodel_MISSING.csv'
]]></error></testcase><testcase classname="pyvter.tests.test_pt_iterators.Test_pt_mathmethods_flat" name="test1" time="0.000"><error type="exceptions.IOError" message="[Errno 2] No such file or directory: 'data/error~subjectXtimeofdayXcourseXmodel_MISSING.csv'"><![CDATA[Traceback (most recent call last):
  File "/usr/lib/python2.7/unittest/case.py", line 329, in run
    testMethod()
  File "/home/jhd/Documents/Projects/pyvter/tests/test_pt_iterators.py", line 133, in test1
    df.read_tbl('data/error~subjectXtimeofdayXcourseXmodel_MISSING.csv')
  File "/home/jhd/Documents/Projects/pyvter/base.py", line 199, in read_tbl
    fid = open(fname, 'r')
IOError: [Errno 2] No such file or directory: 'data/error~subjectXtimeofdayXcourseXmodel_MISSING.csv'
]]></error></testcase><testcase classname="pyvter.tests.test_pt_iterators.Test_pt_mathmethods_flat" name="test2" time="0.000"><error type="exceptions.IOError" message="[Errno 2] No such file or directory: 'data/error~subjectXtimeofdayXcourseXmodel_MISSING.csv'"><![CDATA[Traceback (most recent call last):
  File "/usr/lib/python2.7/unittest/case.py", line 329, in run
    testMethod()
  File "/home/jhd/Documents/Projects/pyvter/tests/test_pt_iterators.py", line 145, in test2
    df.read_tbl('data/error~subjectXtimeofdayXcourseXmodel_MISSING.csv')
  File "/home/jhd/Documents/Projects/pyvter/base.py", line 199, in read_tbl
    fid = open(fname, 'r')
IOError: [Errno 2] No such file or directory: 'data/error~subjectXtimeofdayXcourseXmodel_MISSING.csv'
]]></error></testcase><testcase classname="pyvter.tests.test_pt_iterators.Test_pt_mathmethods_flat" name="test3" time="0.000"><error type="exceptions.IOError" message="[Errno 2] No such file or directory: 'data/error~subjectXtimeofdayXcourseXmodel_MISSING.csv'"><![CDATA[Traceback (most recent call last):
  File "/usr/lib/python2.7/unittest/case.py", line 329, in run
    testMethod()
  File "/home/jhd/Documents/Projects/pyvter/tests/test_pt_iterators.py", line 157, in test3
    df.read_tbl('data/error~subjectXtimeofdayXcourseXmodel_MISSING.csv')
  File "/home/jhd/Documents/Projects/pyvter/base.py", line 199, in read_tbl
    fid = open(fname, 'r')
IOError: [Errno 2] No such file or directory: 'data/error~subjectXtimeofdayXcourseXmodel_MISSING.csv'
]]></error></testcase><testcase classname="pyvter.tests.test_pt_iterators.Test_pt_mathmethods_ndenumerate" name="test1" time="0.000"><error type="exceptions.IOError" message="[Errno 2] No such file or directory: 'data/error~subjectXtimeofdayXcourseXmodel_MISSING.csv'"><![CDATA[Traceback (most recent call last):
  File "/usr/lib/python2.7/unittest/case.py", line 329, in run
    testMethod()
  File "/home/jhd/Documents/Projects/pyvter/tests/test_pt_iterators.py", line 173, in test1
    df.read_tbl('data/error~subjectXtimeofdayXcourseXmodel_MISSING.csv')
  File "/home/jhd/Documents/Projects/pyvter/base.py", line 199, in read_tbl
    fid = open(fname, 'r')
IOError: [Errno 2] No such file or directory: 'data/error~subjectXtimeofdayXcourseXmodel_MISSING.csv'
]]></error></testcase><testcase classname="pyvter.tests.test_pt_iterators.Test_pt_mathmethods_ndenumerate" name="test2" time="0.000"><error type="exceptions.IOError" message="[Errno 2] No such file or directory: 'data/error~subjectXtimeofdayXcourseXmodel_MISSING.csv'"><![CDATA[Traceback (most recent call last):
  File "/usr/lib/python2.7/unittest/case.py", line 329, in run
    testMethod()
  File "/home/jhd/Documents/Projects/pyvter/tests/test_pt_iterators.py", line 190, in test2
    df.read_tbl('data/error~subjectXtimeofdayXcourseXmodel_MISSING.csv')
  File "/home/jhd/Documents/Projects/pyvter/base.py", line 199, in read_tbl
    fid = open(fname, 'r')
IOError: [Errno 2] No such file or directory: 'data/error~subjectXtimeofdayXcourseXmodel_MISSING.csv'
]]></error></testcase><testcase classname="pyvter.tests.test_pt_iterators.Test_pt_mathmethods_ndenumerate" name="test3" time="0.000"><error type="exceptions.IOError" message="[Errno 2] No such file or directory: 'data/error~subjectXtimeofdayXcourseXmodel_MISSING.csv'"><![CDATA[Traceback (most recent call last):
  File "/usr/lib/python2.7/unittest/case.py", line 329, in run
    testMethod()
  File "/home/jhd/Documents/Projects/pyvter/tests/test_pt_iterators.py", line 207, in test3
    df.read_tbl('data/error~subjectXtimeofdayXcourseXmodel_MISSING.csv')
  File "/home/jhd/Documents/Projects/pyvter/base.py", line 199, in read_tbl
    fid = open(fname, 'r')
IOError: [Errno 2] No such file or directory: 'data/error~subjectXtimeofdayXcourseXmodel_MISSING.csv'
]]></error></testcase><testcase classname="pyvter.tests.test_pt_mathmethods.Test_pt_mathmethods__add__" name="test0" time="0.000"><error type="exceptions.IOError" message="[Errno 2] No such file or directory: 'data/error~subjectXtimeofdayXcourseXmodel_MISSING.csv'"><![CDATA[Traceback (most recent call last):
  File "/usr/lib/python2.7/unittest/case.py", line 329, in run
    testMethod()
  File "/home/jhd/Documents/Projects/pyvter/tests/test_pt_mathmethods.py", line 38, in test0
    df.read_tbl('data/error~subjectXtimeofdayXcourseXmodel_MISSING.csv')
  File "/home/jhd/Documents/Projects/pyvter/base.py", line 199, in read_tbl
    fid = open(fname, 'r')
IOError: [Errno 2] No such file or directory: 'data/error~subjectXtimeofdayXcourseXmodel_MISSING.csv'
]]></error></testcase><testcase classname="pyvter.tests.test_pt_mathmethods.Test_pt_mathmethods__add__" name="test1" time="0.000"><error type="exceptions.IOError" message="[Errno 2] No such file or directory: 'data/error~subjectXtimeofdayXcourseXmodel_MISSING.csv'"><![CDATA[Traceback (most recent call last):
  File "/usr/lib/python2.7/unittest/case.py", line 329, in run
    testMethod()
  File "/home/jhd/Documents/Projects/pyvter/tests/test_pt_mathmethods.py", line 58, in test1
    df.read_tbl('data/error~subjectXtimeofdayXcourseXmodel_MISSING.csv')
  File "/home/jhd/Documents/Projects/pyvter/base.py", line 199, in read_tbl
    fid = open(fname, 'r')
IOError: [Errno 2] No such file or directory: 'data/error~subjectXtimeofdayXcourseXmodel_MISSING.csv'
]]></error></testcase><testcase classname="pyvter.tests.test_pt_mathmethods.Test_pt_mathmethods__add__" name="test2" time="0.000"><error type="exceptions.IOError" message="[Errno 2] No such file or directory: 'data/error~subjectXtimeofdayXcourseXmodel_MISSING.csv'"><![CDATA[Traceback (most recent call last):
  File "/usr/lib/python2.7/unittest/case.py", line 329, in run
    testMethod()
  File "/home/jhd/Documents/Projects/pyvter/tests/test_pt_mathmethods.py", line 74, in test2
    df.read_tbl('data/error~subjectXtimeofdayXcourseXmodel_MISSING.csv')
  File "/home/jhd/Documents/Projects/pyvter/base.py", line 199, in read_tbl
    fid = open(fname, 'r')
IOError: [Errno 2] No such file or directory: 'data/error~subjectXtimeofdayXcourseXmodel_MISSING.csv'
]]></error></testcase><testcase classname="pyvter.tests.test_pt_mathmethods.Test_pt_mathmethods__mul__" name="test0" time="0.000"><error type="exceptions.IOError" message="[Errno 2] No such file or directory: 'data/error~subjectXtimeofdayXcourseXmodel_MISSING.csv'"><![CDATA[Traceback (most recent call last):
  File "/usr/lib/python2.7/unittest/case.py", line 329, in run
    testMethod()
  File "/home/jhd/Documents/Projects/pyvter/tests/test_pt_mathmethods.py", line 95, in test0
    df.read_tbl('data/error~subjectXtimeofdayXcourseXmodel_MISSING.csv')
  File "/home/jhd/Documents/Projects/pyvter/base.py", line 199, in read_tbl
    fid = open(fname, 'r')
IOError: [Errno 2] No such file or directory: 'data/error~subjectXtimeofdayXcourseXmodel_MISSING.csv'
]]></error></testcase><testcase classname="pyvter.tests.test_pt_mathmethods.Test_pt_mathmethods__mul__" name="test1" time="0.000"><error type="exceptions.IOError" message="[Errno 2] No such file or directory: 'data/error~subjectXtimeofdayXcourseXmodel_MISSING.csv'"><![CDATA[Traceback (most recent call last):
  File "/usr/lib/python2.7/unittest/case.py", line 329, in run
    testMethod()
  File "/home/jhd/Documents/Projects/pyvter/tests/test_pt_mathmethods.py", line 115, in test1
    df.read_tbl('data/error~subjectXtimeofdayXcourseXmodel_MISSING.csv')
  File "/home/jhd/Documents/Projects/pyvter/base.py", line 199, in read_tbl
    fid = open(fname, 'r')
IOError: [Errno 2] No such file or directory: 'data/error~subjectXtimeofdayXcourseXmodel_MISSING.csv'
]]></error></testcase><testcase classname="pyvter.tests.test_pt_mathmethods.Test_pt_mathmethods__mul__" name="test2" time="0.000"><error type="exceptions.IOError" message="[Errno 2] No such file or directory: 'data/error~subjectXtimeofdayXcourseXmodel_MISSING.csv'"><![CDATA[Traceback (most recent call last):
  File "/usr/lib/python2.7/unittest/case.py", line 329, in run
    testMethod()
  File "/home/jhd/Documents/Projects/pyvter/tests/test_pt_mathmethods.py", line 137, in test2
    df.read_tbl('data/error~subjectXtimeofdayXcourseXmodel_MISSING.csv')
  File "/home/jhd/Documents/Projects/pyvter/base.py", line 199, in read_tbl
    fid = open(fname, 'r')
IOError: [Errno 2] No such file or directory: 'data/error~subjectXtimeofdayXcourseXmodel_MISSING.csv'
]]></error></testcase><testcase classname="pyvter.tests.test_pt_mathmethods.Test_pt_mathmethods_sum" name="test0" time="0.000"><error type="exceptions.IOError" message="[Errno 2] No such file or directory: 'data/error~subjectXtimeofdayXcourseXmodel_MISSING.csv'"><![CDATA[Traceback (most recent call last):
  File "/usr/lib/python2.7/unittest/case.py", line 329, in run
    testMethod()
  File "/home/jhd/Documents/Projects/pyvter/tests/test_pt_mathmethods.py", line 160, in test0
    df.read_tbl('data/error~subjectXtimeofdayXcourseXmodel_MISSING.csv')
  File "/home/jhd/Documents/Projects/pyvter/base.py", line 199, in read_tbl
    fid = open(fname, 'r')
IOError: [Errno 2] No such file or directory: 'data/error~subjectXtimeofdayXcourseXmodel_MISSING.csv'
]]></error></testcase><testcase classname="pyvter.tests.test_pt_run.Test_pivot_0" name="test1" time="0.004"></testcase><testcase classname="pyvter.tests.test_pt_run.Test_pivot_0" name="test2" time="0.003"></testcase><testcase classname="pyvter.tests.test_pt_run.Test_pivot_0" name="test3" time="0.001"><error type="exceptions.ValueError" message="The truth value of an array with more than one element is ambiguous. Use a.any() or a.all()"><![CDATA[Traceback (most recent call last):
  File "/usr/lib/python2.7/unittest/case.py", line 329, in run
    testMethod()
  File "/home/jhd/Documents/Projects/pyvter/tests/test_pt_run.py", line 92, in test3
    self.assertEqual(R,str(my_pivot))
  File "/home/jhd/Documents/Projects/pyvter/base.py", line 2452, in __str__
    if self == []:
  File "/home/jhd/.local/share/virtualenvs/pyvter-QwCYsgP0/local/lib/python2.7/site-packages/numpy/ma/core.py", line 4031, in __eq__
    return self._comparison(other, operator.eq)
  File "/home/jhd/.local/share/virtualenvs/pyvter-QwCYsgP0/local/lib/python2.7/site-packages/numpy/ma/core.py", line 4003, in _comparison
    return masked if mask else check
ValueError: The truth value of an array with more than one element is ambiguous. Use a.any() or a.all()
]]></error></testcase><testcase classname="pyvter.tests.test_pt_run.Test_pivot_0" name="test4" time="0.001"><error type="exceptions.ValueError" message="The truth value of an array with more than one element is ambiguous. Use a.any() or a.all()"><![CDATA[Traceback (most recent call last):
  File "/usr/lib/python2.7/unittest/case.py", line 329, in run
    testMethod()
  File "/home/jhd/Documents/Projects/pyvter/tests/test_pt_run.py", line 115, in test4
    self.assertEqual(R,str(my_pivot))
  File "/home/jhd/Documents/Projects/pyvter/base.py", line 2452, in __str__
    if self == []:
  File "/home/jhd/.local/share/virtualenvs/pyvter-QwCYsgP0/local/lib/python2.7/site-packages/numpy/ma/core.py", line 4031, in __eq__
    return self._comparison(other, operator.eq)
  File "/home/jhd/.local/share/virtualenvs/pyvter-QwCYsgP0/local/lib/python2.7/site-packages/numpy/ma/core.py", line 4003, in _comparison
    return masked if mask else check
ValueError: The truth value of an array with more than one element is ambiguous. Use a.any() or a.all()
]]></error></testcase><testcase classname="pyvter.tests.test_pt_run.Test_pivot_1" name="test1" time="0.001"><error type="exceptions.ValueError" message="The truth value of an array with more than one element is ambiguous. Use a.any() or a.all()"><![CDATA[Traceback (most recent call last):
  File "/usr/lib/python2.7/unittest/case.py", line 329, in run
    testMethod()
  File "/home/jhd/Documents/Projects/pyvter/tests/test_pt_run.py", line 141, in test1
    self.assertEqual(R,str(my_pivot))
  File "/home/jhd/Documents/Projects/pyvter/base.py", line 2452, in __str__
    if self == []:
  File "/home/jhd/.local/share/virtualenvs/pyvter-QwCYsgP0/local/lib/python2.7/site-packages/numpy/ma/core.py", line 4031, in __eq__
    return self._comparison(other, operator.eq)
  File "/home/jhd/.local/share/virtualenvs/pyvter-QwCYsgP0/local/lib/python2.7/site-packages/numpy/ma/core.py", line 4003, in _comparison
    return masked if mask else check
ValueError: The truth value of an array with more than one element is ambiguous. Use a.any() or a.all()
]]></error></testcase><testcase classname="pyvter.tests.test_pt_run.Test_pivot_1" name="test2" time="0.002"><error type="exceptions.ValueError" message="The truth value of an array with more than one element is ambiguous. Use a.any() or a.all()"><![CDATA[Traceback (most recent call last):
  File "/usr/lib/python2.7/unittest/case.py", line 329, in run
    testMethod()
  File "/home/jhd/Documents/Projects/pyvter/tests/test_pt_run.py", line 167, in test2
    self.assertEqual(R,str(my_pivot))
  File "/home/jhd/Documents/Projects/pyvter/base.py", line 2452, in __str__
    if self == []:
  File "/home/jhd/.local/share/virtualenvs/pyvter-QwCYsgP0/local/lib/python2.7/site-packages/numpy/ma/core.py", line 4031, in __eq__
    return self._comparison(other, operator.eq)
  File "/home/jhd/.local/share/virtualenvs/pyvter-QwCYsgP0/local/lib/python2.7/site-packages/numpy/ma/core.py", line 4003, in _comparison
    return masked if mask else check
ValueError: The truth value of an array with more than one element is ambiguous. Use a.any() or a.all()
]]></error></testcase><testcase classname="pyvter.tests.test_pt_run.Test_pivot_1" name="test3" time="0.002"><error type="exceptions.ValueError" message="The truth value of an array with more than one element is ambiguous. Use a.any() or a.all()"><![CDATA[Traceback (most recent call last):
  File "/usr/lib/python2.7/unittest/case.py", line 329, in run
    testMethod()
  File "/home/jhd/Documents/Projects/pyvter/tests/test_pt_run.py", line 195, in test3
    self.assertEqual(R,str(my_pivot))
  File "/home/jhd/Documents/Projects/pyvter/base.py", line 2452, in __str__
    if self == []:
  File "/home/jhd/.local/share/virtualenvs/pyvter-QwCYsgP0/local/lib/python2.7/site-packages/numpy/ma/core.py", line 4031, in __eq__
    return self._comparison(other, operator.eq)
  File "/home/jhd/.local/share/virtualenvs/pyvter-QwCYsgP0/local/lib/python2.7/site-packages/numpy/ma/core.py", line 4003, in _comparison
    return masked if mask else check
ValueError: The truth value of an array with more than one element is ambiguous. Use a.any() or a.all()
]]></error></testcase><testcase classname="pyvter.tests.test_pt_run.Test_pivot_1" name="test4" time="0.002"><error type="exceptions.ValueError" message="The truth value of an array with more than one element is ambiguous. Use a.any() or a.all()"><![CDATA[Traceback (most recent call last):
  File "/usr/lib/python2.7/unittest/case.py", line 329, in run
    testMethod()
  File "/home/jhd/Documents/Projects/pyvter/tests/test_pt_run.py", line 221, in test4
    self.assertEqual(R,str(my_pivot))
  File "/home/jhd/Documents/Projects/pyvter/base.py", line 2452, in __str__
    if self == []:
  File "/home/jhd/.local/share/virtualenvs/pyvter-QwCYsgP0/local/lib/python2.7/site-packages/numpy/ma/core.py", line 4031, in __eq__
    return self._comparison(other, operator.eq)
  File "/home/jhd/.local/share/virtualenvs/pyvter-QwCYsgP0/local/lib/python2.7/site-packages/numpy/ma/core.py", line 4003, in _comparison
    return masked if mask else check
ValueError: The truth value of an array with more than one element is ambiguous. Use a.any() or a.all()
]]></error></testcase><testcase classname="pyvter.tests.test_pt_run.Test_pivot_2" name="test0" time="0.000"><error type="exceptions.IOError" message="[Errno 2] No such file or directory: 'data/words~ageXcondition.csv'"><![CDATA[Traceback (most recent call last):
  File "/usr/lib/python2.7/unittest/case.py", line 320, in run
    self.setUp()
  File "/home/jhd/Documents/Projects/pyvter/tests/test_pt_run.py", line 233, in setUp
    self.df.read_tbl('data/words~ageXcondition.csv')
  File "/home/jhd/Documents/Projects/pyvter/base.py", line 199, in read_tbl
    fid = open(fname, 'r')
IOError: [Errno 2] No such file or directory: 'data/words~ageXcondition.csv'
]]></error></testcase><testcase classname="pyvter.tests.test_pt_run.Test_pivot_2" name="test001" time="0.000"><error type="exceptions.IOError" message="[Errno 2] No such file or directory: 'data/words~ageXcondition.csv'"><![CDATA[Traceback (most recent call last):
  File "/usr/lib/python2.7/unittest/case.py", line 320, in run
    self.setUp()
  File "/home/jhd/Documents/Projects/pyvter/tests/test_pt_run.py", line 233, in setUp
    self.df.read_tbl('data/words~ageXcondition.csv')
  File "/home/jhd/Documents/Projects/pyvter/base.py", line 199, in read_tbl
    fid = open(fname, 'r')
IOError: [Errno 2] No such file or directory: 'data/words~ageXcondition.csv'
]]></error></testcase><testcase classname="pyvter.tests.test_pt_run.Test_pivot_2" name="test002" time="0.000"><error type="exceptions.IOError" message="[Errno 2] No such file or directory: 'data/words~ageXcondition.csv'"><![CDATA[Traceback (most recent call last):
  File "/usr/lib/python2.7/unittest/case.py", line 320, in run
    self.setUp()
  File "/home/jhd/Documents/Projects/pyvter/tests/test_pt_run.py", line 233, in setUp
    self.df.read_tbl('data/words~ageXcondition.csv')
  File "/home/jhd/Documents/Projects/pyvter/base.py", line 199, in read_tbl
    fid = open(fname, 'r')
IOError: [Errno 2] No such file or directory: 'data/words~ageXcondition.csv'
]]></error></testcase><testcase classname="pyvter.tests.test_pt_run.Test_pivot_2" name="test003" time="0.000"><error type="exceptions.IOError" message="[Errno 2] No such file or directory: 'data/words~ageXcondition.csv'"><![CDATA[Traceback (most recent call last):
  File "/usr/lib/python2.7/unittest/case.py", line 320, in run
    self.setUp()
  File "/home/jhd/Documents/Projects/pyvter/tests/test_pt_run.py", line 233, in setUp
    self.df.read_tbl('data/words~ageXcondition.csv')
  File "/home/jhd/Documents/Projects/pyvter/base.py", line 199, in read_tbl
    fid = open(fname, 'r')
IOError: [Errno 2] No such file or directory: 'data/words~ageXcondition.csv'
]]></error></testcase><testcase classname="pyvter.tests.test_pt_run.Test_pivot_2" name="test004" time="0.000"><error type="exceptions.IOError" message="[Errno 2] No such file or directory: 'data/words~ageXcondition.csv'"><![CDATA[Traceback (most recent call last):
  File "/usr/lib/python2.7/unittest/case.py", line 320, in run
    self.setUp()
  File "/home/jhd/Documents/Projects/pyvter/tests/test_pt_run.py", line 233, in setUp
    self.df.read_tbl('data/words~ageXcondition.csv')
  File "/home/jhd/Documents/Projects/pyvter/base.py", line 199, in read_tbl
    fid = open(fname, 'r')
IOError: [Errno 2] No such file or directory: 'data/words~ageXcondition.csv'
]]></error></testcase><testcase classname="pyvter.tests.test_pt_run.Test_pivot_2" name="test005" time="0.000"><error type="exceptions.IOError" message="[Errno 2] No such file or directory: 'data/words~ageXcondition.csv'"><![CDATA[Traceback (most recent call last):
  File "/usr/lib/python2.7/unittest/case.py", line 320, in run
    self.setUp()
  File "/home/jhd/Documents/Projects/pyvter/tests/test_pt_run.py", line 233, in setUp
    self.df.read_tbl('data/words~ageXcondition.csv')
  File "/home/jhd/Documents/Projects/pyvter/base.py", line 199, in read_tbl
    fid = open(fname, 'r')
IOError: [Errno 2] No such file or directory: 'data/words~ageXcondition.csv'
]]></error></testcase><testcase classname="pyvter.tests.test_pt_run.Test_pivot_2" name="test0051" time="0.000"><error type="exceptions.IOError" message="[Errno 2] No such file or directory: 'data/words~ageXcondition.csv'"><![CDATA[Traceback (most recent call last):
  File "/usr/lib/python2.7/unittest/case.py", line 320, in run
    self.setUp()
  File "/home/jhd/Documents/Projects/pyvter/tests/test_pt_run.py", line 233, in setUp
    self.df.read_tbl('data/words~ageXcondition.csv')
  File "/home/jhd/Documents/Projects/pyvter/base.py", line 199, in read_tbl
    fid = open(fname, 'r')
IOError: [Errno 2] No such file or directory: 'data/words~ageXcondition.csv'
]]></error></testcase><testcase classname="pyvter.tests.test_pt_run.Test_pivot_2" name="test006" time="0.000"><error type="exceptions.IOError" message="[Errno 2] No such file or directory: 'data/words~ageXcondition.csv'"><![CDATA[Traceback (most recent call last):
  File "/usr/lib/python2.7/unittest/case.py", line 320, in run
    self.setUp()
  File "/home/jhd/Documents/Projects/pyvter/tests/test_pt_run.py", line 233, in setUp
    self.df.read_tbl('data/words~ageXcondition.csv')
  File "/home/jhd/Documents/Projects/pyvter/base.py", line 199, in read_tbl
    fid = open(fname, 'r')
IOError: [Errno 2] No such file or directory: 'data/words~ageXcondition.csv'
]]></error></testcase><testcase classname="pyvter.tests.test_pt_run.Test_pivot_2" name="test011" time="0.000"><error type="exceptions.IOError" message="[Errno 2] No such file or directory: 'data/words~ageXcondition.csv'"><![CDATA[Traceback (most recent call last):
  File "/usr/lib/python2.7/unittest/case.py", line 320, in run
    self.setUp()
  File "/home/jhd/Documents/Projects/pyvter/tests/test_pt_run.py", line 233, in setUp
    self.df.read_tbl('data/words~ageXcondition.csv')
  File "/home/jhd/Documents/Projects/pyvter/base.py", line 199, in read_tbl
    fid = open(fname, 'r')
IOError: [Errno 2] No such file or directory: 'data/words~ageXcondition.csv'
]]></error></testcase><testcase classname="pyvter.tests.test_pt_run.Test_pivot_2" name="test1" time="0.000"><error type="exceptions.IOError" message="[Errno 2] No such file or directory: 'data/words~ageXcondition.csv'"><![CDATA[Traceback (most recent call last):
  File "/usr/lib/python2.7/unittest/case.py", line 320, in run
    self.setUp()
  File "/home/jhd/Documents/Projects/pyvter/tests/test_pt_run.py", line 233, in setUp
    self.df.read_tbl('data/words~ageXcondition.csv')
  File "/home/jhd/Documents/Projects/pyvter/base.py", line 199, in read_tbl
    fid = open(fname, 'r')
IOError: [Errno 2] No such file or directory: 'data/words~ageXcondition.csv'
]]></error></testcase><testcase classname="pyvter.tests.test_pt_run.Test_pivot_2" name="test3" time="0.000"><error type="exceptions.IOError" message="[Errno 2] No such file or directory: 'data/words~ageXcondition.csv'"><![CDATA[Traceback (most recent call last):
  File "/usr/lib/python2.7/unittest/case.py", line 320, in run
    self.setUp()
  File "/home/jhd/Documents/Projects/pyvter/tests/test_pt_run.py", line 233, in setUp
    self.df.read_tbl('data/words~ageXcondition.csv')
  File "/home/jhd/Documents/Projects/pyvter/base.py", line 199, in read_tbl
    fid = open(fname, 'r')
IOError: [Errno 2] No such file or directory: 'data/words~ageXcondition.csv'
]]></error></testcase><testcase classname="pyvter.tests.test_pt_run.Test_pivot_2" name="test4" time="0.000"><error type="exceptions.IOError" message="[Errno 2] No such file or directory: 'data/words~ageXcondition.csv'"><![CDATA[Traceback (most recent call last):
  File "/usr/lib/python2.7/unittest/case.py", line 320, in run
    self.setUp()
  File "/home/jhd/Documents/Projects/pyvter/tests/test_pt_run.py", line 233, in setUp
    self.df.read_tbl('data/words~ageXcondition.csv')
  File "/home/jhd/Documents/Projects/pyvter/base.py", line 199, in read_tbl
    fid = open(fname, 'r')
IOError: [Errno 2] No such file or directory: 'data/words~ageXcondition.csv'
]]></error></testcase><testcase classname="pyvter.tests.test_pt_run.Test_pivot_2" name="test5" time="0.000"><error type="exceptions.IOError" message="[Errno 2] No such file or directory: 'data/words~ageXcondition.csv'"><![CDATA[Traceback (most recent call last):
  File "/usr/lib/python2.7/unittest/case.py", line 320, in run
    self.setUp()
  File "/home/jhd/Documents/Projects/pyvter/tests/test_pt_run.py", line 233, in setUp
    self.df.read_tbl('data/words~ageXcondition.csv')
  File "/home/jhd/Documents/Projects/pyvter/base.py", line 199, in read_tbl
    fid = open(fname, 'r')
IOError: [Errno 2] No such file or directory: 'data/words~ageXcondition.csv'
]]></error></testcase><testcase classname="pyvter.tests.test_pt_run.Test_pivot_2" name="test6" time="0.000"><error type="exceptions.IOError" message="[Errno 2] No such file or directory: 'data/words~ageXcondition.csv'"><![CDATA[Traceback (most recent call last):
  File "/usr/lib/python2.7/unittest/case.py", line 320, in run
    self.setUp()
  File "/home/jhd/Documents/Projects/pyvter/tests/test_pt_run.py", line 233, in setUp
    self.df.read_tbl('data/words~ageXcondition.csv')
  File "/home/jhd/Documents/Projects/pyvter/base.py", line 199, in read_tbl
    fid = open(fname, 'r')
IOError: [Errno 2] No such file or directory: 'data/words~ageXcondition.csv'
]]></error></testcase><testcase classname="pyvter.tests.test_pt_run.Test_pivot_2" name="test7" time="0.000"><error type="exceptions.IOError" message="[Errno 2] No such file or directory: 'data/words~ageXcondition.csv'"><![CDATA[Traceback (most recent call last):
  File "/usr/lib/python2.7/unittest/case.py", line 320, in run
    self.setUp()
  File "/home/jhd/Documents/Projects/pyvter/tests/test_pt_run.py", line 233, in setUp
    self.df.read_tbl('data/words~ageXcondition.csv')
  File "/home/jhd/Documents/Projects/pyvter/base.py", line 199, in read_tbl
    fid = open(fname, 'r')
IOError: [Errno 2] No such file or directory: 'data/words~ageXcondition.csv'
]]></error></testcase><testcase classname="pyvter.tests.test_pt_run.Test_pivot_3" name="test0" time="0.000"><error type="exceptions.IOError" message="[Errno 2] No such file or directory: 'data/error~subjectXtimeofdayXcourseXmodel_MISSING.csv'"><![CDATA[Traceback (most recent call last):
  File "/usr/lib/python2.7/unittest/case.py", line 320, in run
    self.setUp()
  File "/home/jhd/Documents/Projects/pyvter/tests/test_pt_run.py", line 485, in setUp
    self.df.read_tbl('data/error~subjectXtimeofdayXcourseXmodel_MISSING.csv')
  File "/home/jhd/Documents/Projects/pyvter/base.py", line 199, in read_tbl
    fid = open(fname, 'r')
IOError: [Errno 2] No such file or directory: 'data/error~subjectXtimeofdayXcourseXmodel_MISSING.csv'
]]></error></testcase><testcase classname="pyvter.tests.test_pt_run.Test_pivot_3" name="test1" time="0.000"><error type="exceptions.IOError" message="[Errno 2] No such file or directory: 'data/error~subjectXtimeofdayXcourseXmodel_MISSING.csv'"><![CDATA[Traceback (most recent call last):
  File "/usr/lib/python2.7/unittest/case.py", line 320, in run
    self.setUp()
  File "/home/jhd/Documents/Projects/pyvter/tests/test_pt_run.py", line 485, in setUp
    self.df.read_tbl('data/error~subjectXtimeofdayXcourseXmodel_MISSING.csv')
  File "/home/jhd/Documents/Projects/pyvter/base.py", line 199, in read_tbl
    fid = open(fname, 'r')
IOError: [Errno 2] No such file or directory: 'data/error~subjectXtimeofdayXcourseXmodel_MISSING.csv'
]]></error></testcase><testcase classname="pyvter.tests.test_pt_run.Test_pivot_3" name="test2" time="0.000"><error type="exceptions.IOError" message="[Errno 2] No such file or directory: 'data/error~subjectXtimeofdayXcourseXmodel_MISSING.csv'"><![CDATA[Traceback (most recent call last):
  File "/usr/lib/python2.7/unittest/case.py", line 320, in run
    self.setUp()
  File "/home/jhd/Documents/Projects/pyvter/tests/test_pt_run.py", line 485, in setUp
    self.df.read_tbl('data/error~subjectXtimeofdayXcourseXmodel_MISSING.csv')
  File "/home/jhd/Documents/Projects/pyvter/base.py", line 199, in read_tbl
    fid = open(fname, 'r')
IOError: [Errno 2] No such file or directory: 'data/error~subjectXtimeofdayXcourseXmodel_MISSING.csv'
]]></error></testcase><testcase classname="pyvter.tests.test_pt_run.Test_pivot_3" name="test3" time="0.000"><error type="exceptions.IOError" message="[Errno 2] No such file or directory: 'data/error~subjectXtimeofdayXcourseXmodel_MISSING.csv'"><![CDATA[Traceback (most recent call last):
  File "/usr/lib/python2.7/unittest/case.py", line 320, in run
    self.setUp()
  File "/home/jhd/Documents/Projects/pyvter/tests/test_pt_run.py", line 485, in setUp
    self.df.read_tbl('data/error~subjectXtimeofdayXcourseXmodel_MISSING.csv')
  File "/home/jhd/Documents/Projects/pyvter/base.py", line 199, in read_tbl
    fid = open(fname, 'r')
IOError: [Errno 2] No such file or directory: 'data/error~subjectXtimeofdayXcourseXmodel_MISSING.csv'
]]></error></testcase><testcase classname="pyvter.tests.test_pt_to_dataframe.Test_pyvter_to_dataframe" name="test0" time="0.000"><error type="exceptions.IOError" message="[Errno 2] No such file or directory: 'data/example.csv'"><![CDATA[Traceback (most recent call last):
  File "/usr/lib/python2.7/unittest/case.py", line 329, in run
    testMethod()
  File "/home/jhd/Documents/Projects/pyvter/tests/test_pt_to_dataframe.py", line 34, in test0
    df.read_tbl('data/example.csv')
  File "/home/jhd/Documents/Projects/pyvter/base.py", line 199, in read_tbl
    fid = open(fname, 'r')
IOError: [Errno 2] No such file or directory: 'data/example.csv'
]]></error></testcase><testcase classname="pyvter.tests.test_pt_to_dataframe.Test_pyvter_to_dataframe" name="test1" time="0.000"><error type="exceptions.IOError" message="[Errno 2] No such file or directory: 'data/suppression~subjectXgroupXageXcycleXphase.csv'"><![CDATA[Traceback (most recent call last):
  File "/usr/lib/python2.7/unittest/case.py", line 329, in run
    testMethod()
  File "/home/jhd/Documents/Projects/pyvter/tests/test_pt_to_dataframe.py", line 55, in test1
    df.read_tbl('data/suppression~subjectXgroupXageXcycleXphase.csv')
  File "/home/jhd/Documents/Projects/pyvter/base.py", line 199, in read_tbl
    fid = open(fname, 'r')
IOError: [Errno 2] No such file or directory: 'data/suppression~subjectXgroupXageXcycleXphase.csv'
]]></error></testcase><testcase classname="pyvter.tests.test_pt_to_dataframe.Test_pyvter_to_dataframe" name="test2" time="0.000"><error type="exceptions.IOError" message="[Errno 2] No such file or directory: 'data/suppression~subjectXgroupXageXcycleXphase.csv'"><![CDATA[Traceback (most recent call last):
  File "/usr/lib/python2.7/unittest/case.py", line 329, in run
    testMethod()
  File "/home/jhd/Documents/Projects/pyvter/tests/test_pt_to_dataframe.py", line 70, in test2
    df.read_tbl('data/suppression~subjectXgroupXageXcycleXphase.csv')
  File "/home/jhd/Documents/Projects/pyvter/base.py", line 199, in read_tbl
    fid = open(fname, 'r')
IOError: [Errno 2] No such file or directory: 'data/suppression~subjectXgroupXageXcycleXphase.csv'
]]></error></testcase><testcase classname="pyvter.tests.test_pt_to_dataframe.Test_pyvter_to_dataframe" name="test3" time="0.000"><error type="exceptions.IOError" message="[Errno 2] No such file or directory: 'data/suppression~subjectXgroupXageXcycleXphase.csv'"><![CDATA[Traceback (most recent call last):
  File "/usr/lib/python2.7/unittest/case.py", line 329, in run
    testMethod()
  File "/home/jhd/Documents/Projects/pyvter/tests/test_pt_to_dataframe.py", line 88, in test3
    df.read_tbl('data/suppression~subjectXgroupXageXcycleXphase.csv')
  File "/home/jhd/Documents/Projects/pyvter/base.py", line 199, in read_tbl
    fid = open(fname, 'r')
IOError: [Errno 2] No such file or directory: 'data/suppression~subjectXgroupXageXcycleXphase.csv'
]]></error></testcase><testcase classname="pyvter.tests.test_pt_transpose.Test_pt_transpose" name="test0" time="0.000"><error type="exceptions.IOError" message="[Errno 2] No such file or directory: 'data/error~subjectXtimeofdayXcourseXmodel_MISSING.csv'"><![CDATA[Traceback (most recent call last):
  File "/usr/lib/python2.7/unittest/case.py", line 329, in run
    testMethod()
  File "/home/jhd/Documents/Projects/pyvter/tests/test_pt_transpose.py", line 38, in test0
    df.read_tbl('data/error~subjectXtimeofdayXcourseXmodel_MISSING.csv')
  File "/home/jhd/Documents/Projects/pyvter/base.py", line 199, in read_tbl
    fid = open(fname, 'r')
IOError: [Errno 2] No such file or directory: 'data/error~subjectXtimeofdayXcourseXmodel_MISSING.csv'
]]></error></testcase><testcase classname="pyvter.tests.test_pt_transpose.Test_pt_transpose" name="test1" time="0.000"><error type="exceptions.IOError" message="[Errno 2] No such file or directory: 'data/error~subjectXtimeofdayXcourseXmodel_MISSING.csv'"><![CDATA[Traceback (most recent call last):
  File "/usr/lib/python2.7/unittest/case.py", line 329, in run
    testMethod()
  File "/home/jhd/Documents/Projects/pyvter/tests/test_pt_transpose.py", line 54, in test1
    df.read_tbl('data/error~subjectXtimeofdayXcourseXmodel_MISSING.csv')
  File "/home/jhd/Documents/Projects/pyvter/base.py", line 199, in read_tbl
    fid = open(fname, 'r')
IOError: [Errno 2] No such file or directory: 'data/error~subjectXtimeofdayXcourseXmodel_MISSING.csv'
]]></error></testcase><testcase classname="pyvter.tests.test_pt_transpose.Test_pt_transpose" name="test2" time="0.000"><error type="exceptions.IOError" message="[Errno 2] No such file or directory: 'data/error~subjectXtimeofdayXcourseXmodel_MISSING.csv'"><![CDATA[Traceback (most recent call last):
  File "/usr/lib/python2.7/unittest/case.py", line 329, in run
    testMethod()
  File "/home/jhd/Documents/Projects/pyvter/tests/test_pt_transpose.py", line 76, in test2
    df.read_tbl('data/error~subjectXtimeofdayXcourseXmodel_MISSING.csv')
  File "/home/jhd/Documents/Projects/pyvter/base.py", line 199, in read_tbl
    fid = open(fname, 'r')
IOError: [Errno 2] No such file or directory: 'data/error~subjectXtimeofdayXcourseXmodel_MISSING.csv'
]]></error></testcase><testcase classname="pyvter.tests.test_stats_anova1way.Test_anova1way" name="test0" time="0.004"></testcase><testcase classname="pyvter.tests.test_stats_anova1way.Test_anova1way" name="test1" time="0.004"><failure type="exceptions.AssertionError" message="&quot;Anova: Single Factor on Measure\n\nSUMMARY\nGroups   Count   Sum    Average   Variance \n==========================================\nA           14    870    62.143    202.132 \nB           15    858    57.200    584.743 \nC           16   1510    94.375    339.583 \n\nO'BRIEN TEST FOR HOMOGENEITY OF VARIANCE\nSource of Variation       SS        df       MS         F     P-value   eta^2   Obs. power \n==========================================================================================\nTreatments            1097753.830    2   548876.915   4.065     0.024   0.162        0.641 \nError                 5670427.632   42   135010.182                                        \n==========================================================================================\nTotal                 6768181.462   44                                                     \n\nANOVA\nSource of Variation      SS       df      MS        F       P-value    eta^2   Obs. power \n=========================================================================================\nTreatments            12656.047    2   6328.023   16.707   4.589e-06   0.443        0.978 \nError                 15907.864   42    378.759                                           \n=========================================================================================\nTotal                 28563.911   44                                                      \n\nPOSTHOC MULTIPLE COMPARISONS\n\nTukey HSD: Table of q-statistics\n    A      B          C     \n===========================\nA   0   0.950 ns   6.197 ** \nB       0          7.147 ** \nC                  0        \n===========================\n  + p &lt; .10 (q-critical[3, 42] = 2.9836166391724004)\n  * p &lt; .05 (q-critical[3, 42] = 3.4356970960072437)\n ** p &lt; .01 (q-critical[3, 42] = 4.354320540406892)&quot; != &quot;Anova: Single Factor on Measure\n\nSUMMARY\nGroups   Count   Sum    Average   Variance \n==========================================\nA           14    870    62.143    202.132 \nB           15    858    57.200    584.743 \nC           16   1510    94.375    339.583 \n\nO'BRIEN TEST FOR HOMOGENEITY OF VARIANCE\nSource of Variation       SS        df       MS         F     P-value   eta^2   Obs. power \n==========================================================================================\nTreatments            1097753.830    2   548876.915   4.065     0.024   0.162        0.641 \nError                 5670427.632   42   135010.182                                        \n==========================================================================================\nTotal                 6768181.462   44                                                     \n\nANOVA\nSource of Variation      SS       df      MS        F       P-value    eta^2   Obs. power \n=========================================================================================\nTreatments            12656.047    2   6328.023   16.707   4.589e-06   0.443        0.978 \nError                 15907.864   42    378.759                                           \n=========================================================================================\nTotal                 28563.911   44                                                      \n\nPOSTHOC MULTIPLE COMPARISONS\n\nTukey HSD: Table of q-statistics\n    A      B          C     \n===========================\nA   0   0.950 ns   6.197 ** \nB       0          7.147 ** \nC                  0        \n===========================\n  + p &lt; .10 (q-critical[3, 42] = 2.98361663917)\n  * p &lt; .05 (q-critical[3, 42] = 3.43569709601)\n ** p &lt; .01 (q-critical[3, 42] = 4.35432054041)&quot;"><![CDATA[Traceback (most recent call last):
  File "/usr/lib/python2.7/unittest/case.py", line 329, in run
    testMethod()
  File "/home/jhd/Documents/Projects/pyvter/tests/test_stats_anova1way.py", line 161, in test1
    self.assertEqual(str(D),R)
  File "/usr/lib/python2.7/unittest/case.py", line 513, in assertEqual
    assertion_func(first, second, msg=msg)
  File "/usr/lib/python2.7/unittest/case.py", line 506, in _baseAssertEqual
    raise self.failureException(msg)
AssertionError: "Anova: Single Factor on Measure\n\nSUMMARY\nGroups   Count   Sum    Average   Variance \n==========================================\nA           14    870    62.143    202.132 \nB           15    858    57.200    584.743 \nC           16   1510    94.375    339.583 \n\nO'BRIEN TEST FOR HOMOGENEITY OF VARIANCE\nSource of Variation       SS        df       MS         F     P-value   eta^2   Obs. power \n==========================================================================================\nTreatments            1097753.830    2   548876.915   4.065     0.024   0.162        0.641 \nError                 5670427.632   42   135010.182                                        \n==========================================================================================\nTotal                 6768181.462   44                                                     \n\nANOVA\nSource of Variation      SS       df      MS        F       P-value    eta^2   Obs. power \n=========================================================================================\nTreatments            12656.047    2   6328.023   16.707   4.589e-06   0.443        0.978 \nError                 15907.864   42    378.759                                           \n=========================================================================================\nTotal                 28563.911   44                                                      \n\nPOSTHOC MULTIPLE COMPARISONS\n\nTukey HSD: Table of q-statistics\n    A      B          C     \n===========================\nA   0   0.950 ns   6.197 ** \nB       0          7.147 ** \nC                  0        \n===========================\n  + p < .10 (q-critical[3, 42] = 2.9836166391724004)\n  * p < .05 (q-critical[3, 42] = 3.4356970960072437)\n ** p < .01 (q-critical[3, 42] = 4.354320540406892)" != "Anova: Single Factor on Measure\n\nSUMMARY\nGroups   Count   Sum    Average   Variance \n==========================================\nA           14    870    62.143    202.132 \nB           15    858    57.200    584.743 \nC           16   1510    94.375    339.583 \n\nO'BRIEN TEST FOR HOMOGENEITY OF VARIANCE\nSource of Variation       SS        df       MS         F     P-value   eta^2   Obs. power \n==========================================================================================\nTreatments            1097753.830    2   548876.915   4.065     0.024   0.162        0.641 \nError                 5670427.632   42   135010.182                                        \n==========================================================================================\nTotal                 6768181.462   44                                                     \n\nANOVA\nSource of Variation      SS       df      MS        F       P-value    eta^2   Obs. power \n=========================================================================================\nTreatments            12656.047    2   6328.023   16.707   4.589e-06   0.443        0.978 \nError                 15907.864   42    378.759                                           \n=========================================================================================\nTotal                 28563.911   44                                                      \n\nPOSTHOC MULTIPLE COMPARISONS\n\nTukey HSD: Table of q-statistics\n    A      B          C     \n===========================\nA   0   0.950 ns   6.197 ** \nB       0          7.147 ** \nC                  0        \n===========================\n  + p < .10 (q-critical[3, 42] = 2.98361663917)\n  * p < .05 (q-critical[3, 42] = 3.43569709601)\n ** p < .01 (q-critical[3, 42] = 4.35432054041)"
]]></failure></testcase><testcase classname="pyvter.tests.test_stats_anova1way.Test_anova1way" name="test11" time="0.004"></testcase><testcase classname="pyvter.tests.test_stats_anova1way.Test_anova1way" name="test2" time="0.000"><error type="exceptions.IOError" message="[Errno 2] No such file or directory: 'data/suppression~subjectXgroupXageXcycleXphase.csv'"><![CDATA[Traceback (most recent call last):
  File "/usr/lib/python2.7/unittest/case.py", line 329, in run
    testMethod()
  File "/home/jhd/Documents/Projects/pyvter/tests/test_stats_anova1way.py", line 250, in test2
    df.read_tbl('data/suppression~subjectXgroupXageXcycleXphase.csv')
  File "/home/jhd/Documents/Projects/pyvter/base.py", line 199, in read_tbl
    fid = open(fname, 'r')
IOError: [Errno 2] No such file or directory: 'data/suppression~subjectXgroupXageXcycleXphase.csv'
]]></error></testcase><testcase classname="pyvter.tests.test_stats_anova1way.Test_anova1way" name="test3" time="0.004"><failure type="exceptions.AssertionError" message="&quot;Anova: Single Factor on Measure\n\nSUMMARY\nGroups   Count     Sum     Average   Variance \n=============================================\nA           10   431.400    43.140      9.000 \nB           10   894.400    89.440      4.920 \nC           10   679.500    67.950      4.703 \nD           10   404.700    40.470      5.936 \n\nO'BRIEN TEST FOR HOMOGENEITY OF VARIANCE\nSource of Variation      SS      df     MS       F     P-value   eta^2   Obs. power \n===================================================================================\nTreatments             117.768    3   39.256   0.601     0.619   0.048        0.170 \nError                 2351.332   36   65.315                                        \n===================================================================================\nTotal                 2469.100   39                                                 \n\nANOVA\nSource of Variation      SS       df      MS         F       P-value    eta^2   Obs. power \n==========================================================================================\nTreatments            15953.466    3   5317.822   866.118   1.341e-33   0.986        1.000 \nError                   221.034   36      6.140                                            \n==========================================================================================\nTotal                 16174.500   39                                                       \n\nPOSTHOC MULTIPLE COMPARISONS\n\nTukey HSD: Table of q-statistics\n    A       B           C           D     \n=========================================\nA   0   59.088 **   31.663 **   3.407 +   \nB       0           27.426 **   62.496 ** \nC                   0           35.070 ** \nD                               0         \n=========================================\n  + p &lt; .10 (q-critical[4, 36] = 3.360951299983447)\n  * p &lt; .05 (q-critical[4, 36] = 3.808836787096229)\n ** p &lt; .01 (q-critical[4, 36] = 4.7296619422207185)&quot; != &quot;Anova: Single Factor on Measure\n\nSUMMARY\nGroups   Count     Sum     Average   Variance \n=============================================\nA           10   431.400    43.140      9.000 \nB           10   894.400    89.440      4.920 \nC           10   679.500    67.950      4.703 \nD           10   404.700    40.470      5.936 \n\nO'BRIEN TEST FOR HOMOGENEITY OF VARIANCE\nSource of Variation      SS      df     MS       F     P-value   eta^2   Obs. power \n===================================================================================\nTreatments             117.768    3   39.256   0.601     0.619   0.048        0.170 \nError                 2351.332   36   65.315                                        \n===================================================================================\nTotal                 2469.100   39                                                 \n\nANOVA\nSource of Variation      SS       df      MS         F       P-value    eta^2   Obs. power \n==========================================================================================\nTreatments            15953.466    3   5317.822   866.118   1.341e-33   0.986        1.000 \nError                   221.034   36      6.140                                            \n==========================================================================================\nTotal                 16174.500   39                                                       \n\nPOSTHOC MULTIPLE COMPARISONS\n\nTukey HSD: Table of q-statistics\n    A       B           C           D     \n=========================================\nA   0   59.088 **   31.663 **   3.407 +   \nB       0           27.426 **   62.496 ** \nC                   0           35.070 ** \nD                               0         \n=========================================\n  + p &lt; .10 (q-critical[4, 36] = 3.36095129998)\n  * p &lt; .05 (q-critical[4, 36] = 3.8088367871)\n ** p &lt; .01 (q-critical[4, 36] = 4.72966194222)&quot;"><![CDATA[Traceback (most recent call last):
  File "/usr/lib/python2.7/unittest/case.py", line 329, in run
    testMethod()
  File "/home/jhd/Documents/Projects/pyvter/tests/test_stats_anova1way.py", line 306, in test3
    self.assertEqual(str(D),R)
  File "/usr/lib/python2.7/unittest/case.py", line 513, in assertEqual
    assertion_func(first, second, msg=msg)
  File "/usr/lib/python2.7/unittest/case.py", line 506, in _baseAssertEqual
    raise self.failureException(msg)
AssertionError: "Anova: Single Factor on Measure\n\nSUMMARY\nGroups   Count     Sum     Average   Variance \n=============================================\nA           10   431.400    43.140      9.000 \nB           10   894.400    89.440      4.920 \nC           10   679.500    67.950      4.703 \nD           10   404.700    40.470      5.936 \n\nO'BRIEN TEST FOR HOMOGENEITY OF VARIANCE\nSource of Variation      SS      df     MS       F     P-value   eta^2   Obs. power \n===================================================================================\nTreatments             117.768    3   39.256   0.601     0.619   0.048        0.170 \nError                 2351.332   36   65.315                                        \n===================================================================================\nTotal                 2469.100   39                                                 \n\nANOVA\nSource of Variation      SS       df      MS         F       P-value    eta^2   Obs. power \n==========================================================================================\nTreatments            15953.466    3   5317.822   866.118   1.341e-33   0.986        1.000 \nError                   221.034   36      6.140                                            \n==========================================================================================\nTotal                 16174.500   39                                                       \n\nPOSTHOC MULTIPLE COMPARISONS\n\nTukey HSD: Table of q-statistics\n    A       B           C           D     \n=========================================\nA   0   59.088 **   31.663 **   3.407 +   \nB       0           27.426 **   62.496 ** \nC                   0           35.070 ** \nD                               0         \n=========================================\n  + p < .10 (q-critical[4, 36] = 3.360951299983447)\n  * p < .05 (q-critical[4, 36] = 3.808836787096229)\n ** p < .01 (q-critical[4, 36] = 4.7296619422207185)" != "Anova: Single Factor on Measure\n\nSUMMARY\nGroups   Count     Sum     Average   Variance \n=============================================\nA           10   431.400    43.140      9.000 \nB           10   894.400    89.440      4.920 \nC           10   679.500    67.950      4.703 \nD           10   404.700    40.470      5.936 \n\nO'BRIEN TEST FOR HOMOGENEITY OF VARIANCE\nSource of Variation      SS      df     MS       F     P-value   eta^2   Obs. power \n===================================================================================\nTreatments             117.768    3   39.256   0.601     0.619   0.048        0.170 \nError                 2351.332   36   65.315                                        \n===================================================================================\nTotal                 2469.100   39                                                 \n\nANOVA\nSource of Variation      SS       df      MS         F       P-value    eta^2   Obs. power \n==========================================================================================\nTreatments            15953.466    3   5317.822   866.118   1.341e-33   0.986        1.000 \nError                   221.034   36      6.140                                            \n==========================================================================================\nTotal                 16174.500   39                                                       \n\nPOSTHOC MULTIPLE COMPARISONS\n\nTukey HSD: Table of q-statistics\n    A       B           C           D     \n=========================================\nA   0   59.088 **   31.663 **   3.407 +   \nB       0           27.426 **   62.496 ** \nC                   0           35.070 ** \nD                               0         \n=========================================\n  + p < .10 (q-critical[4, 36] = 3.36095129998)\n  * p < .05 (q-critical[4, 36] = 3.8088367871)\n ** p < .01 (q-critical[4, 36] = 4.72966194222)"
]]></failure></testcase><testcase classname="pyvter.tests.test_stats_anova_between.Test_anova_between" name="test2" time="0.000"><error type="exceptions.IOError" message="[Errno 2] No such file or directory: 'data/words~ageXcondition.csv'"><![CDATA[Traceback (most recent call last):
  File "/usr/lib/python2.7/unittest/case.py", line 329, in run
    testMethod()
  File "/home/jhd/Documents/Projects/pyvter/tests/test_stats_anova_between.py", line 76, in test2
    df.read_tbl(fname)
  File "/home/jhd/Documents/Projects/pyvter/base.py", line 199, in read_tbl
    fid = open(fname, 'r')
IOError: [Errno 2] No such file or directory: 'data/words~ageXcondition.csv'
]]></error></testcase><testcase classname="pyvter.tests.test_stats_anova_mixed.Test_anova_mixed" name="test3" time="0.000"><error type="exceptions.IOError" message="[Errno 2] No such file or directory: 'data/suppression~subjectXgroupXcycleXphase.csv'"><![CDATA[Traceback (most recent call last):
  File "/usr/lib/python2.7/unittest/case.py", line 329, in run
    testMethod()
  File "/home/jhd/Documents/Projects/pyvter/tests/test_stats_anova_mixed.py", line 184, in test3
    df.read_tbl(fname)
  File "/home/jhd/Documents/Projects/pyvter/base.py", line 199, in read_tbl
    fid = open(fname, 'r')
IOError: [Errno 2] No such file or directory: 'data/suppression~subjectXgroupXcycleXphase.csv'
]]></error></testcase><testcase classname="pyvter.tests.test_stats_anova_transform.Test_anova_transform" name="test1" time="0.000"><error type="exceptions.IOError" message="[Errno 2] No such file or directory: 'data/error~subjectXtimeofdayXcourseXmodel.csv'"><![CDATA[Traceback (most recent call last):
  File "/usr/lib/python2.7/unittest/case.py", line 329, in run
    testMethod()
  File "/home/jhd/Documents/Projects/pyvter/tests/test_stats_anova_transform.py", line 186, in test1
    df.read_tbl(fname)
  File "/home/jhd/Documents/Projects/pyvter/base.py", line 199, in read_tbl
    fid = open(fname, 'r')
IOError: [Errno 2] No such file or directory: 'data/error~subjectXtimeofdayXcourseXmodel.csv'
]]></error></testcase><testcase classname="pyvter.tests.test_stats_anova_within.Test_anova_within" name="test0" time="0.000"><error type="exceptions.IOError" message="[Errno 2] No such file or directory: 'data/error~subjectXtimeofdayXcourseXmodel.csv'"><![CDATA[Traceback (most recent call last):
  File "/usr/lib/python2.7/unittest/case.py", line 329, in run
    testMethod()
  File "/home/jhd/Documents/Projects/pyvter/tests/test_stats_anova_within.py", line 186, in test0
    df.read_tbl(fname)
  File "/home/jhd/Documents/Projects/pyvter/base.py", line 199, in read_tbl
    fid = open(fname, 'r')
IOError: [Errno 2] No such file or directory: 'data/error~subjectXtimeofdayXcourseXmodel.csv'
]]></error></testcase><testcase classname="pyvter.tests.test_stats_chisquare1way.Test_chisquare1way" name="test0" time="0.002"></testcase><testcase classname="pyvter.tests.test_stats_chisquare1way.Test_chisquare1way" name="test1" time="0.000"><error type="exceptions.IOError" message="[Errno 2] No such file or directory: 'data/chi_test.csv'"><![CDATA[Traceback (most recent call last):
  File "/usr/lib/python2.7/unittest/case.py", line 329, in run
    testMethod()
  File "/home/jhd/Documents/Projects/pyvter/tests/test_stats_chisquare1way.py", line 86, in test1
    df.read_tbl('data/chi_test.csv')
  File "/home/jhd/Documents/Projects/pyvter/base.py", line 199, in read_tbl
    fid = open(fname, 'r')
IOError: [Errno 2] No such file or directory: 'data/chi_test.csv'
]]></error></testcase><testcase classname="pyvter.tests.test_stats_chisquare1way.Test_chisquare1way" name="test2" time="0.000"><error type="exceptions.IOError" message="[Errno 2] No such file or directory: 'data/chi_test.csv'"><![CDATA[Traceback (most recent call last):
  File "/usr/lib/python2.7/unittest/case.py", line 329, in run
    testMethod()
  File "/home/jhd/Documents/Projects/pyvter/tests/test_stats_chisquare1way.py", line 116, in test2
    df.read_tbl('data/chi_test.csv')
  File "/home/jhd/Documents/Projects/pyvter/base.py", line 199, in read_tbl
    fid = open(fname, 'r')
IOError: [Errno 2] No such file or directory: 'data/chi_test.csv'
]]></error></testcase><testcase classname="pyvter.tests.test_stats_chisquare1way.Test_chisquare1way" name="test3" time="0.001"></testcase><testcase classname="pyvter.tests.test_stats_chisquare2way.Test_chisquare2way" name="test0" time="0.004"></testcase><testcase classname="pyvter.tests.test_stats_chisquare2way.Test_chisquare2way" name="test1" time="0.003"></testcase><testcase classname="pyvter.tests.test_stats_chisquare2way.Test_chisquare2way" name="test2" time="0.002"><failure type="exceptions.AssertionError" message="&quot;ChiSquare2way([('chisq', 25.79364579345589), ('p', 2.5059995107347527e-06), ('df', 2), ('lnchisq', 26.055873891205664), ('lnp', 2.1980566132523407e-06), ('ccchisq', None), ('ccp', None), ('N', 1772.0), ('C', 0.11978058926585373), ('CramerV', 0.12064921681366868), ('CramerV_prob', 3.50998747929475e-07), ('C_prob', 4.26267335738495e-07), ('w', 0.12064921681366868), ('lambda', 25.79364579345589), ('crit_chi2', 5.991464547107979), ('power', 0.9972126130834689)], counter=Counter({('Message', 'Removed'): 499.0, ('Countrol', 'Removed'): 477.0, ('Countrol', 'Litter'): 385.0, ('Message', 'Litter'): 290.0, ('Message', 'Trash Can'): 80.0, ('Countrol', 'Trash Can'): 41.0}), row_counter=Counter({'Countrol': 903.0, 'Message': 869.0}), col_counter=Counter({'Removed': 976.0, 'Litter': 675.0, 'Trash Can': 121.0}), N_r=2, N_c=3)&quot; != &quot;ChiSquare2way([('chisq', 25.79364579345589), ('p', 2.5059995107347527e-06), ('df', 2), ('lnchisq', 26.055873891205664), ('lnp', 2.1980566132523407e-06), ('ccchisq', None), ('ccp', None), ('N', 1772.0), ('C', 0.11978058926585373), ('CramerV', 0.12064921681366868), ('CramerV_prob', 3.50998747929475e-07), ('C_prob', 4.26267335738495e-07), ('w', 0.12064921681366868), ('lambda', 25.79364579345589), ('crit_chi2', 5.9914645471079799), ('power', 0.9972126147810455)], counter=Counter({('Message', 'Removed'): 499.0, ('Countrol', 'Removed'): 477.0, ('Countrol', 'Litter'): 385.0, ('Message', 'Litter'): 290.0, ('Message', 'Trash Can'): 80.0, ('Countrol', 'Trash Can'): 41.0}), row_counter=Counter({'Countrol': 903.0, 'Message': 869.0}), col_counter=Counter({'Removed': 976.0, 'Litter': 675.0, 'Trash Can': 121.0}), N_r=2, N_c=3)&quot;"><![CDATA[Traceback (most recent call last):
  File "/usr/lib/python2.7/unittest/case.py", line 329, in run
    testMethod()
  File "/home/jhd/Documents/Projects/pyvter/tests/test_stats_chisquare2way.py", line 127, in test2
    self.assertEqual(repr(x2), R)
  File "/usr/lib/python2.7/unittest/case.py", line 513, in assertEqual
    assertion_func(first, second, msg=msg)
  File "/usr/lib/python2.7/unittest/case.py", line 506, in _baseAssertEqual
    raise self.failureException(msg)
AssertionError: "ChiSquare2way([('chisq', 25.79364579345589), ('p', 2.5059995107347527e-06), ('df', 2), ('lnchisq', 26.055873891205664), ('lnp', 2.1980566132523407e-06), ('ccchisq', None), ('ccp', None), ('N', 1772.0), ('C', 0.11978058926585373), ('CramerV', 0.12064921681366868), ('CramerV_prob', 3.50998747929475e-07), ('C_prob', 4.26267335738495e-07), ('w', 0.12064921681366868), ('lambda', 25.79364579345589), ('crit_chi2', 5.991464547107979), ('power', 0.9972126130834689)], counter=Counter({('Message', 'Removed'): 499.0, ('Countrol', 'Removed'): 477.0, ('Countrol', 'Litter'): 385.0, ('Message', 'Litter'): 290.0, ('Message', 'Trash Can'): 80.0, ('Countrol', 'Trash Can'): 41.0}), row_counter=Counter({'Countrol': 903.0, 'Message': 869.0}), col_counter=Counter({'Removed': 976.0, 'Litter': 675.0, 'Trash Can': 121.0}), N_r=2, N_c=3)" != "ChiSquare2way([('chisq', 25.79364579345589), ('p', 2.5059995107347527e-06), ('df', 2), ('lnchisq', 26.055873891205664), ('lnp', 2.1980566132523407e-06), ('ccchisq', None), ('ccp', None), ('N', 1772.0), ('C', 0.11978058926585373), ('CramerV', 0.12064921681366868), ('CramerV_prob', 3.50998747929475e-07), ('C_prob', 4.26267335738495e-07), ('w', 0.12064921681366868), ('lambda', 25.79364579345589), ('crit_chi2', 5.9914645471079799), ('power', 0.9972126147810455)], counter=Counter({('Message', 'Removed'): 499.0, ('Countrol', 'Removed'): 477.0, ('Countrol', 'Litter'): 385.0, ('Message', 'Litter'): 290.0, ('Message', 'Trash Can'): 80.0, ('Countrol', 'Trash Can'): 41.0}), row_counter=Counter({'Countrol': 903.0, 'Message': 869.0}), col_counter=Counter({'Removed': 976.0, 'Litter': 675.0, 'Trash Can': 121.0}), N_r=2, N_c=3)"
]]></failure></testcase><testcase classname="pyvter.tests.test_stats_correlation.Test_correlation" name="test0" time="0.001"></testcase><testcase classname="pyvter.tests.test_stats_correlation.Test_correlation" name="test1" time="0.003"><system-out><![CDATA[Bivariate Correlations

                         A           B           C     
======================================================
A   spearman                 1       0.958      -0.924 
    Sig (2-tailed)           .   9.699e-12   2.259e-09 
    N                       21          21          21 
------------------------------------------------------
B   spearman             0.958           1      -0.890 
    Sig (2-tailed)   9.699e-12           .   6.850e-08 
    N                       21          21          21 
------------------------------------------------------
C   spearman            -0.924      -0.890           1 
    Sig (2-tailed)   2.259e-09   6.850e-08           . 
    N                       21          21          21 

Larzelere and Mulaik Significance Testing

 Pair     i   Correlation       P       alpha/(k-i+1)   Sig. 
============================================================
A vs. B   1         0.958   9.699e-12           0.017   **   
A vs. C   2         0.924   2.259e-09           0.025   **   
B vs. C   3         0.890   6.850e-08           0.050   **   
]]></system-out></testcase><testcase classname="pyvter.tests.test_stats_correlation.Test_correlation" name="test2" time="0.000"><error type="exceptions.IOError" message="[Errno 2] No such file or directory: 'data/iqbrainsize.txt'"><![CDATA[Traceback (most recent call last):
  File "/usr/lib/python2.7/unittest/case.py", line 329, in run
    testMethod()
  File "/home/jhd/Documents/Projects/pyvter/tests/test_stats_correlation.py", line 99, in test2
    df.read_tbl('data/iqbrainsize.txt', delimiter='\t')
  File "/home/jhd/Documents/Projects/pyvter/base.py", line 199, in read_tbl
    fid = open(fname, 'r')
IOError: [Errno 2] No such file or directory: 'data/iqbrainsize.txt'
]]></error></testcase><testcase classname="pyvter.tests.test_stats_descriptives.Test_descriptives" name="test0" time="0.000"><error type="exceptions.IOError" message="[Errno 2] No such file or directory: 'data/words~ageXcondition.csv'"><![CDATA[Traceback (most recent call last):
  File "/usr/lib/python2.7/unittest/case.py", line 329, in run
    testMethod()
  File "/home/jhd/Documents/Projects/pyvter/tests/test_stats_descriptives.py", line 43, in test0
    df.read_tbl('data/words~ageXcondition.csv')
  File "/home/jhd/Documents/Projects/pyvter/base.py", line 199, in read_tbl
    fid = open(fname, 'r')
IOError: [Errno 2] No such file or directory: 'data/words~ageXcondition.csv'
]]></error></testcase><testcase classname="pyvter.tests.test_stats_descriptives.Test_descriptives" name="test01" time="0.000"><error type="exceptions.IOError" message="[Errno 2] No such file or directory: 'data/words~ageXcondition.csv'"><![CDATA[Traceback (most recent call last):
  File "/usr/lib/python2.7/unittest/case.py", line 329, in run
    testMethod()
  File "/home/jhd/Documents/Projects/pyvter/tests/test_stats_descriptives.py", line 70, in test01
    df.read_tbl('data/words~ageXcondition.csv')
  File "/home/jhd/Documents/Projects/pyvter/base.py", line 199, in read_tbl
    fid = open(fname, 'r')
IOError: [Errno 2] No such file or directory: 'data/words~ageXcondition.csv'
]]></error></testcase><testcase classname="pyvter.tests.test_stats_descriptives.Test_descriptives" name="test02" time="0.000"><error type="exceptions.IOError" message="[Errno 2] No such file or directory: 'data/words~ageXcondition.csv'"><![CDATA[Traceback (most recent call last):
  File "/usr/lib/python2.7/unittest/case.py", line 329, in run
    testMethod()
  File "/home/jhd/Documents/Projects/pyvter/tests/test_stats_descriptives.py", line 78, in test02
    df.read_tbl('data/words~ageXcondition.csv')
  File "/home/jhd/Documents/Projects/pyvter/base.py", line 199, in read_tbl
    fid = open(fname, 'r')
IOError: [Errno 2] No such file or directory: 'data/words~ageXcondition.csv'
]]></error></testcase><testcase classname="pyvter.tests.test_stats_descriptives.Test_descriptives" name="test1" time="0.000"><error type="exceptions.IOError" message="[Errno 2] No such file or directory: 'data/error~subjectXtimeofdayXcourseXmodel_MISSING.csv'"><![CDATA[Traceback (most recent call last):
  File "/usr/lib/python2.7/unittest/case.py", line 329, in run
    testMethod()
  File "/home/jhd/Documents/Projects/pyvter/tests/test_stats_descriptives.py", line 120, in test1
    df.read_tbl('data/error~subjectXtimeofdayXcourseXmodel_MISSING.csv')
  File "/home/jhd/Documents/Projects/pyvter/base.py", line 199, in read_tbl
    fid = open(fname, 'r')
IOError: [Errno 2] No such file or directory: 'data/error~subjectXtimeofdayXcourseXmodel_MISSING.csv'
]]></error></testcase><testcase classname="pyvter.tests.test_stats_descriptives.Test_descriptives" name="test11" time="0.000"><error type="exceptions.IOError" message="[Errno 2] No such file or directory: 'data/error~subjectXtimeofdayXcourseXmodel_MISSING.csv'"><![CDATA[Traceback (most recent call last):
  File "/usr/lib/python2.7/unittest/case.py", line 329, in run
    testMethod()
  File "/home/jhd/Documents/Projects/pyvter/tests/test_stats_descriptives.py", line 129, in test11
    df.read_tbl('data/error~subjectXtimeofdayXcourseXmodel_MISSING.csv')
  File "/home/jhd/Documents/Projects/pyvter/base.py", line 199, in read_tbl
    fid = open(fname, 'r')
IOError: [Errno 2] No such file or directory: 'data/error~subjectXtimeofdayXcourseXmodel_MISSING.csv'
]]></error></testcase><testcase classname="pyvter.tests.test_stats_histogram.Test_histogram" name="test0" time="0.000"><error type="exceptions.IOError" message="[Errno 2] No such file or directory: 'data/words~ageXcondition.csv'"><![CDATA[Traceback (most recent call last):
  File "/usr/lib/python2.7/unittest/case.py", line 329, in run
    testMethod()
  File "/home/jhd/Documents/Projects/pyvter/tests/test_stats_histogram.py", line 31, in test0
    df.read_tbl('data/words~ageXcondition.csv')
  File "/home/jhd/Documents/Projects/pyvter/base.py", line 199, in read_tbl
    fid = open(fname, 'r')
IOError: [Errno 2] No such file or directory: 'data/words~ageXcondition.csv'
]]></error></testcase><testcase classname="pyvter.tests.test_stats_histogram.Test_histogram" name="test01" time="0.000"><error type="exceptions.IOError" message="[Errno 2] No such file or directory: 'data/words~ageXcondition.csv'"><![CDATA[Traceback (most recent call last):
  File "/usr/lib/python2.7/unittest/case.py", line 329, in run
    testMethod()
  File "/home/jhd/Documents/Projects/pyvter/tests/test_stats_histogram.py", line 40, in test01
    df.read_tbl('data/words~ageXcondition.csv')
  File "/home/jhd/Documents/Projects/pyvter/base.py", line 199, in read_tbl
    fid = open(fname, 'r')
IOError: [Errno 2] No such file or directory: 'data/words~ageXcondition.csv'
]]></error></testcase><testcase classname="pyvter.tests.test_stats_histogram.Test_histogram" name="test02" time="0.000"><error type="exceptions.IOError" message="[Errno 2] No such file or directory: 'data/words~ageXcondition.csv'"><![CDATA[Traceback (most recent call last):
  File "/usr/lib/python2.7/unittest/case.py", line 329, in run
    testMethod()
  File "/home/jhd/Documents/Projects/pyvter/tests/test_stats_histogram.py", line 61, in test02
    df.read_tbl('data/words~ageXcondition.csv')
  File "/home/jhd/Documents/Projects/pyvter/base.py", line 199, in read_tbl
    fid = open(fname, 'r')
IOError: [Errno 2] No such file or directory: 'data/words~ageXcondition.csv'
]]></error></testcase><testcase classname="pyvter.tests.test_stats_marginals.Test_marginals" name="test0" time="0.000"><error type="exceptions.IOError" message="[Errno 2] No such file or directory: 'data/words~ageXcondition.csv'"><![CDATA[Traceback (most recent call last):
  File "/usr/lib/python2.7/unittest/case.py", line 329, in run
    testMethod()
  File "/home/jhd/Documents/Projects/pyvter/tests/test_stats_marginals.py", line 28, in test0
    df.read_tbl('data/words~ageXcondition.csv')
  File "/home/jhd/Documents/Projects/pyvter/base.py", line 199, in read_tbl
    fid = open(fname, 'r')
IOError: [Errno 2] No such file or directory: 'data/words~ageXcondition.csv'
]]></error></testcase><testcase classname="pyvter.tests.test_stats_marginals.Test_marginals" name="test02" time="0.000"><error type="exceptions.IOError" message="[Errno 2] No such file or directory: 'data/words~ageXcondition.csv'"><![CDATA[Traceback (most recent call last):
  File "/usr/lib/python2.7/unittest/case.py", line 329, in run
    testMethod()
  File "/home/jhd/Documents/Projects/pyvter/tests/test_stats_marginals.py", line 68, in test02
    df.read_tbl('data/words~ageXcondition.csv')
  File "/home/jhd/Documents/Projects/pyvter/base.py", line 199, in read_tbl
    fid = open(fname, 'r')
IOError: [Errno 2] No such file or directory: 'data/words~ageXcondition.csv'
]]></error></testcase><testcase classname="pyvter.tests.test_stats_marginals.Test_marginals" name="test03" time="0.000"><error type="exceptions.IOError" message="[Errno 2] No such file or directory: 'data/words~ageXcondition.csv'"><![CDATA[Traceback (most recent call last):
  File "/usr/lib/python2.7/unittest/case.py", line 329, in run
    testMethod()
  File "/home/jhd/Documents/Projects/pyvter/tests/test_stats_marginals.py", line 76, in test03
    df.read_tbl('data/words~ageXcondition.csv')
  File "/home/jhd/Documents/Projects/pyvter/base.py", line 199, in read_tbl
    fid = open(fname, 'r')
IOError: [Errno 2] No such file or directory: 'data/words~ageXcondition.csv'
]]></error></testcase><testcase classname="pyvter.tests.test_stats_marginals.Test_marginals" name="test04" time="0.000"><error type="exceptions.IOError" message="[Errno 2] No such file or directory: 'data/words~ageXcondition.csv'"><![CDATA[Traceback (most recent call last):
  File "/usr/lib/python2.7/unittest/case.py", line 329, in run
    testMethod()
  File "/home/jhd/Documents/Projects/pyvter/tests/test_stats_marginals.py", line 93, in test04
    df.read_tbl('data/words~ageXcondition.csv')
  File "/home/jhd/Documents/Projects/pyvter/base.py", line 199, in read_tbl
    fid = open(fname, 'r')
IOError: [Errno 2] No such file or directory: 'data/words~ageXcondition.csv'
]]></error></testcase><testcase classname="pyvter.tests.test_stats_marginals.Test_marginals" name="test05" time="0.000"><error type="exceptions.IOError" message="[Errno 2] No such file or directory: 'data/words~ageXcondition.csv'"><![CDATA[Traceback (most recent call last):
  File "/usr/lib/python2.7/unittest/case.py", line 329, in run
    testMethod()
  File "/home/jhd/Documents/Projects/pyvter/tests/test_stats_marginals.py", line 103, in test05
    df.read_tbl('data/words~ageXcondition.csv')
  File "/home/jhd/Documents/Projects/pyvter/base.py", line 199, in read_tbl
    fid = open(fname, 'r')
IOError: [Errno 2] No such file or directory: 'data/words~ageXcondition.csv'
]]></error></testcase><testcase classname="pyvter.tests.test_stats_posthoc.Test_posthoc" name="test31" time="0.029"></testcase><testcase classname="pyvter.tests.test_stats_posthoc.Test_posthoc" name="test32" time="0.005"><failure type="exceptions.AssertionError" message="&quot;Anova: Single Factor on Measure\n\nSUMMARY\nGroups    Count   Sum   Average   Variance \n==========================================\nContact      10   300        30    116.444 \nHit          10   350        35     86.444 \nBump         10   380        38    122.222 \nCollide      10   410        41     41.556 \nSmash        10   460        46     33.333 \n\nO'BRIEN TEST FOR HOMOGENEITY OF VARIANCE\nSource of Variation       SS       df      MS         F     P-value   eta^2   Obs. power \n========================================================================================\nTreatments             68081.975    4   17020.494   1.859     0.134   0.142        0.498 \nError                 412050.224   45    9156.672                                        \n========================================================================================\nTotal                 480132.199   49                                                    \n\nANOVA\nSource of Variation    SS    df   MS      F     P-value   eta^2   Obs. power \n============================================================================\nTreatments            1460    4   365   4.562     0.004   0.289        0.837 \nError                 3600   45    80                                        \n============================================================================\nTotal                 5060   49                                              \n\nPOSTHOC MULTIPLE COMPARISONS\n\nTukey HSD: Table of q-statistics\n          Bump   Collide    Contact      Hit       Smash   \n==========================================================\nBump      0      1.061 ns   2.828 ns   1.061 ns   2.828 ns \nCollide          0          3.889 +    2.121 ns   1.768 ns \nContact                     0          1.768 ns   5.657 ** \nHit                                    0          3.889 +  \nSmash                                             0        \n==========================================================\n  + p &lt; .10 (q-critical[5, 45] = 3.590383436745183)\n  * p &lt; .05 (q-critical[5, 45] = 4.018611780038246)\n ** p &lt; .01 (q-critical[5, 45] = 4.8928084298666)&quot; != &quot;Anova: Single Factor on Measure\n\nSUMMARY\nGroups    Count   Sum   Average   Variance \n==========================================\nContact      10   300        30    116.444 \nHit          10   350        35     86.444 \nBump         10   380        38    122.222 \nCollide      10   410        41     41.556 \nSmash        10   460        46     33.333 \n\nO'BRIEN TEST FOR HOMOGENEITY OF VARIANCE\nSource of Variation       SS       df      MS         F     P-value   eta^2   Obs. power \n========================================================================================\nTreatments             68081.975    4   17020.494   1.859     0.134   0.142        0.498 \nError                 412050.224   45    9156.672                                        \n========================================================================================\nTotal                 480132.199   49                                                    \n\nANOVA\nSource of Variation    SS    df   MS      F     P-value   eta^2   Obs. power \n============================================================================\nTreatments            1460    4   365   4.562     0.004   0.289        0.837 \nError                 3600   45    80                                        \n============================================================================\nTotal                 5060   49                                              \n\nPOSTHOC MULTIPLE COMPARISONS\n\nTukey HSD: Table of q-statistics\n          Bump   Collide    Contact      Hit       Smash   \n==========================================================\nBump      0      1.061 ns   2.828 ns   1.061 ns   2.828 ns \nCollide          0          3.889 +    2.121 ns   1.768 ns \nContact                     0          1.768 ns   5.657 ** \nHit                                    0          3.889 +  \nSmash                                             0        \n==========================================================\n  + p &lt; .10 (q-critical[5, 45] = 3.59038343675)\n  * p &lt; .05 (q-critical[5, 45] = 4.01861178004)\n ** p &lt; .01 (q-critical[5, 45] = 4.89280842987)&quot;"><![CDATA[Traceback (most recent call last):
  File "/usr/lib/python2.7/unittest/case.py", line 329, in run
    testMethod()
  File "/home/jhd/Documents/Projects/pyvter/tests/test_stats_posthoc.py", line 140, in test32
    self.assertEqual(str(D),R)
  File "/usr/lib/python2.7/unittest/case.py", line 513, in assertEqual
    assertion_func(first, second, msg=msg)
  File "/usr/lib/python2.7/unittest/case.py", line 506, in _baseAssertEqual
    raise self.failureException(msg)
AssertionError: "Anova: Single Factor on Measure\n\nSUMMARY\nGroups    Count   Sum   Average   Variance \n==========================================\nContact      10   300        30    116.444 \nHit          10   350        35     86.444 \nBump         10   380        38    122.222 \nCollide      10   410        41     41.556 \nSmash        10   460        46     33.333 \n\nO'BRIEN TEST FOR HOMOGENEITY OF VARIANCE\nSource of Variation       SS       df      MS         F     P-value   eta^2   Obs. power \n========================================================================================\nTreatments             68081.975    4   17020.494   1.859     0.134   0.142        0.498 \nError                 412050.224   45    9156.672                                        \n========================================================================================\nTotal                 480132.199   49                                                    \n\nANOVA\nSource of Variation    SS    df   MS      F     P-value   eta^2   Obs. power \n============================================================================\nTreatments            1460    4   365   4.562     0.004   0.289        0.837 \nError                 3600   45    80                                        \n============================================================================\nTotal                 5060   49                                              \n\nPOSTHOC MULTIPLE COMPARISONS\n\nTukey HSD: Table of q-statistics\n          Bump   Collide    Contact      Hit       Smash   \n==========================================================\nBump      0      1.061 ns   2.828 ns   1.061 ns   2.828 ns \nCollide          0          3.889 +    2.121 ns   1.768 ns \nContact                     0          1.768 ns   5.657 ** \nHit                                    0          3.889 +  \nSmash                                             0        \n==========================================================\n  + p < .10 (q-critical[5, 45] = 3.590383436745183)\n  * p < .05 (q-critical[5, 45] = 4.018611780038246)\n ** p < .01 (q-critical[5, 45] = 4.8928084298666)" != "Anova: Single Factor on Measure\n\nSUMMARY\nGroups    Count   Sum   Average   Variance \n==========================================\nContact      10   300        30    116.444 \nHit          10   350        35     86.444 \nBump         10   380        38    122.222 \nCollide      10   410        41     41.556 \nSmash        10   460        46     33.333 \n\nO'BRIEN TEST FOR HOMOGENEITY OF VARIANCE\nSource of Variation       SS       df      MS         F     P-value   eta^2   Obs. power \n========================================================================================\nTreatments             68081.975    4   17020.494   1.859     0.134   0.142        0.498 \nError                 412050.224   45    9156.672                                        \n========================================================================================\nTotal                 480132.199   49                                                    \n\nANOVA\nSource of Variation    SS    df   MS      F     P-value   eta^2   Obs. power \n============================================================================\nTreatments            1460    4   365   4.562     0.004   0.289        0.837 \nError                 3600   45    80                                        \n============================================================================\nTotal                 5060   49                                              \n\nPOSTHOC MULTIPLE COMPARISONS\n\nTukey HSD: Table of q-statistics\n          Bump   Collide    Contact      Hit       Smash   \n==========================================================\nBump      0      1.061 ns   2.828 ns   1.061 ns   2.828 ns \nCollide          0          3.889 +    2.121 ns   1.768 ns \nContact                     0          1.768 ns   5.657 ** \nHit                                    0          3.889 +  \nSmash                                             0        \n==========================================================\n  + p < .10 (q-critical[5, 45] = 3.59038343675)\n  * p < .05 (q-critical[5, 45] = 4.01861178004)\n ** p < .01 (q-critical[5, 45] = 4.89280842987)"
]]></failure></testcase><testcase classname="pyvter.tests.test_stats_ttest_1sample.Test_ttest1sample" name="test0" time="0.001"></testcase><testcase classname="pyvter.tests.test_stats_ttest_1sample.Test_ttest1sample" name="test1" time="0.000"><error type="exceptions.IOError" message="[Errno 2] No such file or directory: 'data/suppression~subjectXgroupXageXcycleXphase.csv'"><![CDATA[Traceback (most recent call last):
  File "/usr/lib/python2.7/unittest/case.py", line 329, in run
    testMethod()
  File "/home/jhd/Documents/Projects/pyvter/tests/test_stats_ttest_1sample.py", line 71, in test1
    df.read_tbl('data/suppression~subjectXgroupXageXcycleXphase.csv')
  File "/home/jhd/Documents/Projects/pyvter/base.py", line 199, in read_tbl
    fid = open(fname, 'r')
IOError: [Errno 2] No such file or directory: 'data/suppression~subjectXgroupXageXcycleXphase.csv'
]]></error></testcase><testcase classname="pyvter.tests.test_stats_ttest_equal.Test_ttest_equal" name="test1" time="0.001"></testcase><testcase classname="pyvter.tests.test_stats_ttest_equal.Test_ttest_equal" name="test11" time="0.002"></testcase><testcase classname="pyvter.tests.test_stats_ttest_paired.Test_ttest_paired" name="test0" time="0.001"></testcase><testcase classname="pyvter.tests.test_stats_ttest_paired.Test_ttest_paired" name="test01" time="0.002"></testcase><testcase classname="pyvter.tests.test_stats_ttest_paired.Test_ttest_paired" name="test4" time="0.000"><error type="exceptions.IOError" message="[Errno 2] No such file or directory: 'data/example2_prepost.csv'"><![CDATA[Traceback (most recent call last):
  File "/usr/lib/python2.7/unittest/case.py", line 329, in run
    testMethod()
  File "/home/jhd/Documents/Projects/pyvter/tests/test_stats_ttest_paired.py", line 109, in test4
    df.read_tbl('data/example2_prepost.csv')
  File "/home/jhd/Documents/Projects/pyvter/base.py", line 199, in read_tbl
    fid = open(fname, 'r')
IOError: [Errno 2] No such file or directory: 'data/example2_prepost.csv'
]]></error></testcase><testcase classname="pyvter.tests.test_stats_ttest_paired.Test_ttest_paired" name="test__repr__" time="0.002"></testcase><testcase classname="pyvter.tests.test_stats_ttest_unequal.Test_ttest_unequal" name="test2" time="0.002"></testcase><testcase classname="pyvter.tests.test_stats_ttest_unequal.Test_ttest_unequal" name="test21" time="0.002"></testcase><testcase classname="pyvter.tests.test_stats_ttest_unequal.Test_ttest_unequal" name="test3" time="0.001"></testcase><testcase classname="pyvter.tests.test_stats_ttest_unequal.Test_ttest_unequal" name="test31" time="0.002"></testcase></testsuite>